Workbook

Sheet オリジナルユニフォーム
Y1: =SUM(N5:Z5) -> 274
A2: リード実績（オリジナルユニフォーム） | B2: 2024年度 | N2: 2025年度 | Y2: =SUM(N9:Y9) -> 45 | Z2: 2026年度 | AC2: 7/1時点 | AL2: 合計 | AM2: 合計 | AN2: 合計
B3: 3月 | C3: 4月 | D3: 5月 | E3: 6月 | F3: 7月 | G3: 8月 | H3: 9月 | I3: 10月 | J3: 11月 | K3: 12月 | L3: 1月 | M3: 2月 | N3: 45717 | O3: 45748 | P3: 45778 | Q3: 45809 | R3: 45839 | S3: 45870 | T3: 45901 | U3: 45931 | V3: 45962 | W3: 45992 | X3: 46023 | Y3: 46054 | Z3: 46082 | AA3: 46113 | AB3: 46143 | AC3: 46174 | AD3: 46204 | AE3: 46235 | AF3: 46266 | AG3: 46296 | AH3: 46327 | AI3: 46357 | AJ3: 46388 | AK3: 46419 | AL3: 2024年度 | AM3: 2025年度 | AN3: 2026年度
A4: MAL | B4: - | C4: - | D4: - | E4: - | F4: - | G4: - | H4: 129 | I4: 911 | J4: 2080 | K4: 1487 | L4: 3187 | M4: 1772 | N4: 2488 | O4: 1959 | P4: 2159 | Q4: 2553 | R4: 5181 | S4: 2621 | T4: 2797 | U4: 3226 | V4: 2881 | W4: 2908 | X4: 3355 | Y4: 3007 | Z4: 3021 | AA4: 3178 | AB4: 2639 | AC4: 4301 | AL4: =SUM(E4:M4) -> 9566 | AM4: =SUM(N4:Y4) -> 35135 | AN4: =SUM(Z4:AK4) -> 13139
A5: MQL | B5: - | C5: - | D5: - | E5: - | F5: - | G5: - | H5: 3 | I5: 7 | J5: 25 | K5: 10 | L5: 16 | M5: 18 | N5: 33 | O5: 20 | P5: 13 | Q5: 15 | R5: 44 | S5: 29 | T5: =COUNTIFS([1]流入チャネル別顧客一覧_7月以降完全ユニークではない!$C:$C,">="&DATE(2025,3,1), [1]流入チャネル別顧客一覧_7月以降完全ユニークではない!$C:$C,"<"&DATE(2026,3,1), [1]流入チャネル別顧客一覧_7月以降完全ユニークではない!$C:$C,">="&T$3, [1]流入チャネル別顧客一覧_7月以降完全ユニークではない!$C:$C,"<"&EDATE(T$3,1) ) -> 30 | U5: =COUNTIFS([1]流入チャネル別顧客一覧_7月以降完全ユニークではない!$C:$C,">="&DATE(2025,3,1), [1]流入チャネル別顧客一覧_7月以降完全ユニークではない!$C:$C,"<"&DATE(2026,3,1), [1]流入チャネル別顧客一覧_7月以降完全ユニークではない!$C:$C,">="&U$3, [1]流入チャネル別顧客一覧_7月以降完全ユニークではない!$C:$C,"<"&EDATE(U$3,1) ) -> 19 | V5: =COUNTIFS([1]流入チャネル別顧客一覧_7月以降完全ユニークではない!$C:$C,">="&DATE(2025,3,1), [1]流入チャネル別顧客一覧_7月以降完全ユニークではない!$C:$C,"<"&DATE(2026,3,1), [1]流入チャネル別顧客一覧_7月以降完全ユニークではない!$C:$C,">="&V$3, [1]流入チャネル別顧客一覧_7月以降完全ユニークではない!$C:$C,"<"&EDATE(V$3,1) ) -> 23 | W5: =COUNTIFS([1]流入チャネル別顧客一覧_7月以降完全ユニークではない!$C:$C,">="&DATE(2025,3,1), [1]流入チャネル別顧客一覧_7月以降完全ユニークではない!$C:$C,"<"&DATE(2026,3,1), [1]流入チャネル別顧客一覧_7月以降完全ユニークではない!$C:$C,">="&W$3, [1]流入チャネル別顧客一覧_7月以降完全ユニークではない!$C:$C,"<"&EDATE(W$3,1) ) -> 14 | X5: =COUNTIFS([1]流入チャネル別顧客一覧_7月以降完全ユニークではない!$C:$C,">="&DATE(2025,3,1), [1]流入チャネル別顧客一覧_7月以降完全ユニークではない!$C:$C,"<"&DATE(2026,3,1), [1]流入チャネル別顧客一覧_7月以降完全ユニークではない!$C:$C,">="&X$3, [1]流入チャネル別顧客一覧_7月以降完全ユニークではない!$C:$C,"<"&EDATE(X$3,1) ) -> 13 | Y5: =COUNTIFS([1]流入チャネル別顧客一覧_7月以降完全ユニークではない!$C:$C,">="&DATE(2025,3,1), [1]流入チャネル別顧客一覧_7月以降完全ユニークではない!$C:$C,"<"&DATE(2026,3,1), [1]流入チャネル別顧客一覧_7月以降完全ユニークではない!$C:$C,">="&Y$3, [1]流入チャネル別顧客一覧_7月以降完全ユニークではない!$C:$C,"<"&EDATE(Y$3,1) ) -> 13 | Z5: =COUNTIFS([1]流入チャネル別顧客一覧_7月以降完全ユニークではない!$C:$C,">="&DATE(2026,3,1), [1]流入チャネル別顧客一覧_7月以降完全ユニークではない!$C:$C,"<"&DATE(2027,3,1), [1]流入チャネル別顧客一覧_7月以降完全ユニークではない!$C:$C,">="&Z$3, [1]流入チャネル別顧客一覧_7月以降完全ユニークではない!$C:$C,"<"&EDATE(Z$3,1) ) -> 8 | AA5: =COUNTIFS([1]流入チャネル別顧客一覧_7月以降完全ユニークではない!$C:$C,">="&DATE(2026,3,1), [1]流入チャネル別顧客一覧_7月以降完全ユニークではない!$C:$C,"<"&DATE(2027,3,1), [1]流入チャネル別顧客一覧_7月以降完全ユニークではない!$C:$C,">="&AA$3, [1]流入チャネル別顧客一覧_7月以降完全ユニークではない!$C:$C,"<"&EDATE(AA$3,1) ) -> 11 | AB5: =COUNTIFS([1]流入チャネル別顧客一覧_7月以降完全ユニークではない!$C:$C,">="&DATE(2026,3,1), [1]流入チャネル別顧客一覧_7月以降完全ユニークではない!$C:$C,"<"&DATE(2027,3,1), [1]流入チャネル別顧客一覧_7月以降完全ユニークではない!$C:$C,">="&AB$3, [1]流入チャネル別顧客一覧_7月以降完全ユニークではない!$C:$C,"<"&EDATE(AB$3,1) ) -> 44 | AC5: =COUNTIFS([1]流入チャネル別顧客一覧_7月以降完全ユニークではない!$C:$C,">="&DATE(2026,3,1), [1]流入チャネル別顧客一覧_7月以降完全ユニークではない!$C:$C,"<"&DATE(2027,3,1), [1]流入チャネル別顧客一覧_7月以降完全ユニークではない!$C:$C,">="&AC$3, [1]流入チャネル別顧客一覧_7月以降完全ユニークではない!$C:$C,"<"&EDATE(AC$3,1) ) -> 22 | AD5: =COUNTIFS([1]流入チャネル別顧客一覧_7月以降完全ユニークではない!$C:$C,">="&DATE(2026,3,1), [1]流入チャネル別顧客一覧_7月以降完全ユニークではない!$C:$C,"<"&DATE(2027,3,1), [1]流入チャネル別顧客一覧_7月以降完全ユニークではない!$C:$C,">="&AD$3, [1]流入チャネル別顧客一覧_7月以降完全ユニークではない!$C:$C,"<"&EDATE(AD$3,1) ) -> 0 | AE5: =COUNTIFS([1]流入チャネル別顧客一覧_7月以降完全ユニークではない!$C:$C,">="&DATE(2026,3,1), [1]流入チャネル別顧客一覧_7月以降完全ユニークではない!$C:$C,"<"&DATE(2027,3,1), [1]流入チャネル別顧客一覧_7月以降完全ユニークではない!$C:$C,">="&AE$3, [1]流入チャネル別顧客一覧_7月以降完全ユニークではない!$C:$C,"<"&EDATE(AE$3,1) ) -> 0 | AF5: =COUNTIFS([1]流入チャネル別顧客一覧_7月以降完全ユニークではない!$C:$C,">="&DATE(2026,3,1), [1]流入チャネル別顧客一覧_7月以降完全ユニークではない!$C:$C,"<"&DATE(2027,3,1), [1]流入チャネル別顧客一覧_7月以降完全ユニークではない!$C:$C,">="&AF$3, [1]流入チャネル別顧客一覧_7月以降完全ユニークではない!$C:$C,"<"&EDATE(AF$3,1) ) -> 0 | AG5: =COUNTIFS([1]流入チャネル別顧客一覧_7月以降完全ユニークではない!$C:$C,">="&DATE(2026,3,1), [1]流入チャネル別顧客一覧_7月以降完全ユニークではない!$C:$C,"<"&DATE(2027,3,1), [1]流入チャネル別顧客一覧_7月以降完全ユニークではない!$C:$C,">="&AG$3, [1]流入チャネル別顧客一覧_7月以降完全ユニークではない!$C:$C,"<"&EDATE(AG$3,1) ) -> 0 | ... AK5: =COUNTIFS([1]流入チャネル別顧客一覧_7月以降完全ユニークではない!$C:$C,">="&DATE(2026,3,1), [1]流入チャネル別顧客一覧_7月以降完全ユニークではない!$C:$C,"<"&DATE(2027,3,1), [1]流入チャネル別顧客一覧_7月以降完全ユニークではない!$C:$C,">="&AK$3, [1]流入チャネル別顧客一覧_7月以降完全ユニークではない!$C:$C,"<"&EDATE(AK$3,1) ) -> 0 | AL5: =SUM(E5:M5) -> 79 | AM5: =SUM(N5:Y5) -> 266 | AN5: =SUM(Z5:AK5) -> 85
A6: MQL率（MQL/MAL） | N6: =N5/N4 -> 0.013263666 | O6: =O5/O4 -> 0.01020929 | P6: =P5/P4 -> 0.0060213062 | Q6: =Q5/Q4 -> 0.0058754407 | R6: =R5/R4 -> 0.008492569 | S6: =S5/S4 -> 0.011064479 | T6: =T5/T4 -> 0.010725778 | U6: =U5/U4 -> 0.0058896466 | ... AN6: =AN5/AN4 -> 0.0064692899
A7: SAL | H7: 0 | I7: 2 | J7: 4 | K7: 1 | L7: 3 | M7: 5 | N7: =COUNTIFS( [1]流入チャネル別顧客一覧_7月以降完全ユニークではない!$C:$C,">="&DATE(2025,3,1), [1]流入チャネル別顧客一覧_7月以降完全ユニークではない!$C:$C,"<"&DATE(2026,3,1), [1]流入チャネル別顧客一覧_7月以降完全ユニークではない!$R:$R,">="&EOMONTH(N$3,-1)+1, [1]流入チャネル別顧客一覧_7月以降完全ユニークではない!$R:$R,"<"&EOMONTH(N$3,0)+1 ) -> 5 | O7: =COUNTIFS( [1]流入チャネル別顧客一覧_7月以降完全ユニークではない!$C:$C,">="&DATE(2025,3,1), [1]流入チャネル別顧客一覧_7月以降完全ユニークではない!$C:$C,"<"&DATE(2026,3,1), [1]流入チャネル別顧客一覧_7月以降完全ユニークではない!$R:$R,">="&EOMONTH(O$3,-1)+1, [1]流入チャネル別顧客一覧_7月以降完全ユニークではない!$R:$R,"<"&EOMONTH(O$3,0)+1 ) -> 4 | P7: =COUNTIFS( [1]流入チャネル別顧客一覧_7月以降完全ユニークではない!$C:$C,">="&DATE(2025,3,1), [1]流入チャネル別顧客一覧_7月以降完全ユニークではない!$C:$C,"<"&DATE(2026,3,1), [1]流入チャネル別顧客一覧_7月以降完全ユニークではない!$R:$R,">="&EOMONTH(P$3,-1)+1, [1]流入チャネル別顧客一覧_7月以降完全ユニークではない!$R:$R,"<"&EOMONTH(P$3,0)+1 ) -> 4 | Q7: =COUNTIFS( [1]流入チャネル別顧客一覧_7月以降完全ユニークではない!$C:$C,">="&DATE(2025,3,1), [1]流入チャネル別顧客一覧_7月以降完全ユニークではない!$C:$C,"<"&DATE(2026,3,1), [1]流入チャネル別顧客一覧_7月以降完全ユニークではない!$R:$R,">="&EOMONTH(Q$3,-1)+1, [1]流入チャネル別顧客一覧_7月以降完全ユニークではない!$R:$R,"<"&EOMONTH(Q$3,0)+1 ) -> 4 | R7: =COUNTIFS( [1]流入チャネル別顧客一覧_7月以降完全ユニークではない!$C:$C,">="&DATE(2025,3,1), [1]流入チャネル別顧客一覧_7月以降完全ユニークではない!$C:$C,"<"&DATE(2026,3,1), [1]流入チャネル別顧客一覧_7月以降完全ユニークではない!$R:$R,">="&EOMONTH(R$3,-1)+1, [1]流入チャネル別顧客一覧_7月以降完全ユニークではない!$R:$R,"<"&EOMONTH(R$3,0)+1 ) -> 8 | S7: =COUNTIFS( [1]流入チャネル別顧客一覧_7月以降完全ユニークではない!$C:$C,">="&DATE(2025,3,1), [1]流入チャネル別顧客一覧_7月以降完全ユニークではない!$C:$C,"<"&DATE(2026,3,1), [1]流入チャネル別顧客一覧_7月以降完全ユニークではない!$R:$R,">="&EOMONTH(S$3,-1)+1, [1]流入チャネル別顧客一覧_7月以降完全ユニークではない!$R:$R,"<"&EOMONTH(S$3,0)+1 ) -> 4 | T7: =COUNTIFS( [1]流入チャネル別顧客一覧_7月以降完全ユニークではない!$C:$C,">="&DATE(2025,3,1), [1]流入チャネル別顧客一覧_7月以降完全ユニークではない!$C:$C,"<"&DATE(2026,3,1), [1]流入チャネル別顧客一覧_7月以降完全ユニークではない!$R:$R,">="&EOMONTH(T$3,-1)+1, [1]流入チャネル別顧客一覧_7月以降完全ユニークではない!$R:$R,"<"&EOMONTH(T$3,0)+1 ) -> 6 | U7: =COUNTIFS( [1]流入チャネル別顧客一覧_7月以降完全ユニークではない!$C:$C,">="&DATE(2025,3,1), [1]流入チャネル別顧客一覧_7月以降完全ユニークではない!$C:$C,"<"&DATE(2026,3,1), [1]流入チャネル別顧客一覧_7月以降完全ユニークではない!$R:$R,">="&EOMONTH(U$3,-1)+1, [1]流入チャネル別顧客一覧_7月以降完全ユニークではない!$R:$R,"<"&EOMONTH(U$3,0)+1 ) -> 3 | ... Y7: =COUNTIFS( [1]流入チャネル別顧客一覧_7月以降完全ユニークではない!$C:$C,">="&DATE(2025,3,1), [1]流入チャネル別顧客一覧_7月以降完全ユニークではない!$C:$C,"<"&DATE(2026,3,1), [1]流入チャネル別顧客一覧_7月以降完全ユニークではない!$R:$R,">="&EOMONTH(Y$3,-1)+1, [1]流入チャネル別顧客一覧_7月以降完全ユニークではない!$R:$R,"<"&EOMONTH(Y$3,0)+1 ) -> 3 | Z7: =COUNTIFS( [1]流入チャネル別顧客一覧_7月以降完全ユニークではない!$C:$C,">="&DATE(2026,3,1), [1]流入チャネル別顧客一覧_7月以降完全ユニークではない!$C:$C,"<"&DATE(2027,3,1), [1]流入チャネル別顧客一覧_7月以降完全ユニークではない!$R:$R,">="&EOMONTH(Z$3,-1)+1, [1]流入チャネル別顧客一覧_7月以降完全ユニークではない!$R:$R,"<"&EOMONTH(Z$3,0)+1 ) -> 1 | AA7: =COUNTIFS( [1]流入チャネル別顧客一覧_7月以降完全ユニークではない!$C:$C,">="&DATE(2026,3,1), [1]流入チャネル別顧客一覧_7月以降完全ユニークではない!$C:$C,"<"&DATE(2027,3,1), [1]流入チャネル別顧客一覧_7月以降完全ユニークではない!$R:$R,">="&EOMONTH(AA$3,-1)+1, [1]流入チャネル別顧客一覧_7月以降完全ユニークではない!$R:$R,"<"&EOMONTH(AA$3,0)+1 ) -> 3 | AB7: =COUNTIFS( [1]流入チャネル別顧客一覧_7月以降完全ユニークではない!$C:$C,">="&DATE(2026,3,1), [1]流入チャネル別顧客一覧_7月以降完全ユニークではない!$C:$C,"<"&DATE(2027,3,1), [1]流入チャネル別顧客一覧_7月以降完全ユニークではない!$R:$R,">="&EOMONTH(AB$3,-1)+1, [1]流入チャネル別顧客一覧_7月以降完全ユニークではない!$R:$R,"<"&EOMONTH(AB$3,0)+1 ) -> 3 | AC7: =COUNTIFS( [1]流入チャネル別顧客一覧_7月以降完全ユニークではない!$C:$C,">="&DATE(2026,3,1), [1]流入チャネル別顧客一覧_7月以降完全ユニークではない!$C:$C,"<"&DATE(2027,3,1), [1]流入チャネル別顧客一覧_7月以降完全ユニークではない!$R:$R,">="&EOMONTH(AC$3,-1)+1, [1]流入チャネル別顧客一覧_7月以降完全ユニークではない!$R:$R,"<"&EOMONTH(AC$3,0)+1 ) -> 6 | AD7: =COUNTIFS( [1]流入チャネル別顧客一覧_7月以降完全ユニークではない!$C:$C,">="&DATE(2026,3,1), [1]流入チャネル別顧客一覧_7月以降完全ユニークではない!$C:$C,"<"&DATE(2027,3,1), [1]流入チャネル別顧客一覧_7月以降完全ユニークではない!$R:$R,">="&EOMONTH(AD$3,-1)+1, [1]流入チャネル別顧客一覧_7月以降完全ユニークではない!$R:$R,"<"&EOMONTH(AD$3,0)+1 ) -> 0 | AE7: =COUNTIFS( [1]流入チャネル別顧客一覧_7月以降完全ユニークではない!$C:$C,">="&DATE(2026,3,1), [1]流入チャネル別顧客一覧_7月以降完全ユニークではない!$C:$C,"<"&DATE(2027,3,1), [1]流入チャネル別顧客一覧_7月以降完全ユニークではない!$R:$R,">="&EOMONTH(AE$3,-1)+1, [1]流入チャネル別顧客一覧_7月以降完全ユニークではない!$R:$R,"<"&EOMONTH(AE$3,0)+1 ) -> 0 | AF7: =COUNTIFS( [1]流入チャネル別顧客一覧_7月以降完全ユニークではない!$C:$C,">="&DATE(2026,3,1), [1]流入チャネル別顧客一覧_7月以降完全ユニークではない!$C:$C,"<"&DATE(2027,3,1), [1]流入チャネル別顧客一覧_7月以降完全ユニークではない!$R:$R,">="&EOMONTH(AF$3,-1)+1, [1]流入チャネル別顧客一覧_7月以降完全ユニークではない!$R:$R,"<"&EOMONTH(AF$3,0)+1 ) -> 0 | AG7: =COUNTIFS( [1]流入チャネル別顧客一覧_7月以降完全ユニークではない!$C:$C,">="&DATE(2026,3,1), [1]流入チャネル別顧客一覧_7月以降完全ユニークではない!$C:$C,"<"&DATE(2027,3,1), [1]流入チャネル別顧客一覧_7月以降完全ユニークではない!$R:$R,">="&EOMONTH(AG$3,-1)+1, [1]流入チャネル別顧客一覧_7月以降完全ユニークではない!$R:$R,"<"&EOMONTH(AG$3,0)+1 ) -> 0 | ... AK7: =COUNTIFS( [1]流入チャネル別顧客一覧_7月以降完全ユニークではない!$C:$C,">="&DATE(2026,3,1), [1]流入チャネル別顧客一覧_7月以降完全ユニークではない!$C:$C,"<"&DATE(2027,3,1), [1]流入チャネル別顧客一覧_7月以降完全ユニークではない!$R:$R,">="&EOMONTH(AK$3,-1)+1, [1]流入チャネル別顧客一覧_7月以降完全ユニークではない!$R:$R,"<"&EOMONTH(AK$3,0)+1 ) -> 0 | AM7: =SUM(N7:Y7) -> 53 | AN7: =SUM(Z7:AK7) -> 13
A8: SAL率（SAL/MQL） | G8: =IF(G7=0,"0%",G7/G5) -> 0% | H8: =IF(H7=0,"0%",H7/H5) -> 0% | I8: =IF(I7=0,"0%",I7/I5) -> 0.28571429 | J8: =IF(J7=0,"0%",J7/J5) -> 0.16 | K8: =IF(K7=0,"0%",K7/K5) -> 0.1 | L8: =IF(L7=0,"0%",L7/L5) -> 0.1875 | M8: =IF(M7=0,"0%",M7/M5) -> 0.27777778 | N8: =IF(N7=0,"0%",N7/N5) -> 0.15151515 | ... AN8: =IF(AN7=0,"0%",AN7/AN5) -> 0.15294118
A9: SQL（案件化数） | B9: - | C9: - | D9: - | E9: - | F9: - | G9: - | H9: 0 | I9: 1 | J9: 5 | K9: 0 | L9: 2 | M9: 1 | N9: =COUNTIFS( [1]流入チャネル別顧客一覧_7月以降完全ユニークではない!$C:$C,">="&DATE(2025,3,1), [1]流入チャネル別顧客一覧_7月以降完全ユニークではない!$C:$C,"<"&DATE(2026,3,1), [1]流入チャネル別顧客一覧_7月以降完全ユニークではない!$S:$S,">="&EOMONTH(N$3,-1)+1, [1]流入チャネル別顧客一覧_7月以降完全ユニークではない!$S:$S,"<"&EOMONTH(N$3,0)+1 ) -> 2 | O9: =COUNTIFS( [1]流入チャネル別顧客一覧_7月以降完全ユニークではない!$C:$C,">="&DATE(2025,3,1), [1]流入チャネル別顧客一覧_7月以降完全ユニークではない!$C:$C,"<"&DATE(2026,3,1), [1]流入チャネル別顧客一覧_7月以降完全ユニークではない!$S:$S,">="&EOMONTH(O$3,-1)+1, [1]流入チャネル別顧客一覧_7月以降完全ユニークではない!$S:$S,"<"&EOMONTH(O$3,0)+1 ) -> 5 | P9: =COUNTIFS( [1]流入チャネル別顧客一覧_7月以降完全ユニークではない!$C:$C,">="&DATE(2025,3,1), [1]流入チャネル別顧客一覧_7月以降完全ユニークではない!$C:$C,"<"&DATE(2026,3,1), [1]流入チャネル別顧客一覧_7月以降完全ユニークではない!$S:$S,">="&EOMONTH(P$3,-1)+1, [1]流入チャネル別顧客一覧_7月以降完全ユニークではない!$S:$S,"<"&EOMONTH(P$3,0)+1 ) -> 3 | Q9: =COUNTIFS( [1]流入チャネル別顧客一覧_7月以降完全ユニークではない!$C:$C,">="&DATE(2025,3,1), [1]流入チャネル別顧客一覧_7月以降完全ユニークではない!$C:$C,"<"&DATE(2026,3,1), [1]流入チャネル別顧客一覧_7月以降完全ユニークではない!$S:$S,">="&EOMONTH(Q$3,-1)+1, [1]流入チャネル別顧客一覧_7月以降完全ユニークではない!$S:$S,"<"&EOMONTH(Q$3,0)+1 ) -> 4 | R9: =COUNTIFS( [1]流入チャネル別顧客一覧_7月以降完全ユニークではない!$C:$C,">="&DATE(2025,3,1), [1]流入チャネル別顧客一覧_7月以降完全ユニークではない!$C:$C,"<"&DATE(2026,3,1), [1]流入チャネル別顧客一覧_7月以降完全ユニークではない!$S:$S,">="&EOMONTH(R$3,-1)+1, [1]流入チャネル別顧客一覧_7月以降完全ユニークではない!$S:$S,"<"&EOMONTH(R$3,0)+1 ) -> 3 | S9: =COUNTIFS( [1]流入チャネル別顧客一覧_7月以降完全ユニークではない!$C:$C,">="&DATE(2025,3,1), [1]流入チャネル別顧客一覧_7月以降完全ユニークではない!$C:$C,"<"&DATE(2026,3,1), [1]流入チャネル別顧客一覧_7月以降完全ユニークではない!$S:$S,">="&EOMONTH(S$3,-1)+1, [1]流入チャネル別顧客一覧_7月以降完全ユニークではない!$S:$S,"<"&EOMONTH(S$3,0)+1 ) -> 6 | T9: =COUNTIFS( [1]流入チャネル別顧客一覧_7月以降完全ユニークではない!$C:$C,">="&DATE(2025,3,1), [1]流入チャネル別顧客一覧_7月以降完全ユニークではない!$C:$C,"<"&DATE(2026,3,1), [1]流入チャネル別顧客一覧_7月以降完全ユニークではない!$S:$S,">="&EOMONTH(T$3,-1)+1, [1]流入チャネル別顧客一覧_7月以降完全ユニークではない!$S:$S,"<"&EOMONTH(T$3,0)+1 ) -> 8 | U9: =COUNTIFS( [1]流入チャネル別顧客一覧_7月以降完全ユニークではない!$C:$C,">="&DATE(2025,3,1), [1]流入チャネル別顧客一覧_7月以降完全ユニークではない!$C:$C,"<"&DATE(2026,3,1), [1]流入チャネル別顧客一覧_7月以降完全ユニークではない!$S:$S,">="&EOMONTH(U$3,-1)+1, [1]流入チャネル別顧客一覧_7月以降完全ユニークではない!$S:$S,"<"&EOMONTH(U$3,0)+1 ) -> 2 | ... Y9: =COUNTIFS( [1]流入チャネル別顧客一覧_7月以降完全ユニークではない!$C:$C,">="&DATE(2025,3,1), [1]流入チャネル別顧客一覧_7月以降完全ユニークではない!$C:$C,"<"&DATE(2026,3,1), [1]流入チャネル別顧客一覧_7月以降完全ユニークではない!$S:$S,">="&EOMONTH(Y$3,-1)+1, [1]流入チャネル別顧客一覧_7月以降完全ユニークではない!$S:$S,"<"&EOMONTH(Y$3,0)+1 ) -> 2 | Z9: =COUNTIFS( [1]流入チャネル別顧客一覧_7月以降完全ユニークではない!$C:$C,">="&DATE(2026,3,1), [1]流入チャネル別顧客一覧_7月以降完全ユニークではない!$C:$C,"<"&DATE(2027,3,1), [1]流入チャネル別顧客一覧_7月以降完全ユニークではない!$S:$S,">="&EOMONTH(Z$3,-1)+1, [1]流入チャネル別顧客一覧_7月以降完全ユニークではない!$S:$S,"<"&EOMONTH(Z$3,0)+1 ) -> 0 | AA9: =COUNTIFS( [1]流入チャネル別顧客一覧_7月以降完全ユニークではない!$C:$C,">="&DATE(2026,3,1), [1]流入チャネル別顧客一覧_7月以降完全ユニークではない!$C:$C,"<"&DATE(2027,3,1), [1]流入チャネル別顧客一覧_7月以降完全ユニークではない!$S:$S,">="&EOMONTH(AA$3,-1)+1, [1]流入チャネル別顧客一覧_7月以降完全ユニークではない!$S:$S,"<"&EOMONTH(AA$3,0)+1 ) -> 1 | AB9: =COUNTIFS( [1]流入チャネル別顧客一覧_7月以降完全ユニークではない!$C:$C,">="&DATE(2026,3,1), [1]流入チャネル別顧客一覧_7月以降完全ユニークではない!$C:$C,"<"&DATE(2027,3,1), [1]流入チャネル別顧客一覧_7月以降完全ユニークではない!$S:$S,">="&EOMONTH(AB$3,-1)+1, [1]流入チャネル別顧客一覧_7月以降完全ユニークではない!$S:$S,"<"&EOMONTH(AB$3,0)+1 ) -> 2 | AC9: =COUNTIFS( [1]流入チャネル別顧客一覧_7月以降完全ユニークではない!$C:$C,">="&DATE(2026,3,1), [1]流入チャネル別顧客一覧_7月以降完全ユニークではない!$C:$C,"<"&DATE(2027,3,1), [1]流入チャネル別顧客一覧_7月以降完全ユニークではない!$S:$S,">="&EOMONTH(AC$3,-1)+1, [1]流入チャネル別顧客一覧_7月以降完全ユニークではない!$S:$S,"<"&EOMONTH(AC$3,0)+1 ) -> 5 | AD9: =COUNTIFS( [1]流入チャネル別顧客一覧_7月以降完全ユニークではない!$C:$C,">="&DATE(2026,3,1), [1]流入チャネル別顧客一覧_7月以降完全ユニークではない!$C:$C,"<"&DATE(2027,3,1), [1]流入チャネル別顧客一覧_7月以降完全ユニークではない!$S:$S,">="&EOMONTH(AD$3,-1)+1, [1]流入チャネル別顧客一覧_7月以降完全ユニークではない!$S:$S,"<"&EOMONTH(AD$3,0)+1 ) -> 0 | AE9: =COUNTIFS( [1]流入チャネル別顧客一覧_7月以降完全ユニークではない!$C:$C,">="&DATE(2026,3,1), [1]流入チャネル別顧客一覧_7月以降完全ユニークではない!$C:$C,"<"&DATE(2027,3,1), [1]流入チャネル別顧客一覧_7月以降完全ユニークではない!$S:$S,">="&EOMONTH(AE$3,-1)+1, [1]流入チャネル別顧客一覧_7月以降完全ユニークではない!$S:$S,"<"&EOMONTH(AE$3,0)+1 ) -> 0 | AF9: =COUNTIFS( [1]流入チャネル別顧客一覧_7月以降完全ユニークではない!$C:$C,">="&DATE(2026,3,1), [1]流入チャネル別顧客一覧_7月以降完全ユニークではない!$C:$C,"<"&DATE(2027,3,1), [1]流入チャネル別顧客一覧_7月以降完全ユニークではない!$S:$S,">="&EOMONTH(AF$3,-1)+1, [1]流入チャネル別顧客一覧_7月以降完全ユニークではない!$S:$S,"<"&EOMONTH(AF$3,0)+1 ) -> 0 | AG9: =COUNTIFS( [1]流入チャネル別顧客一覧_7月以降完全ユニークではない!$C:$C,">="&DATE(2026,3,1), [1]流入チャネル別顧客一覧_7月以降完全ユニークではない!$C:$C,"<"&DATE(2027,3,1), [1]流入チャネル別顧客一覧_7月以降完全ユニークではない!$S:$S,">="&EOMONTH(AG$3,-1)+1, [1]流入チャネル別顧客一覧_7月以降完全ユニークではない!$S:$S,"<"&EOMONTH(AG$3,0)+1 ) -> 0 | ... AK9: =COUNTIFS( [1]流入チャネル別顧客一覧_7月以降完全ユニークではない!$C:$C,">="&DATE(2026,3,1), [1]流入チャネル別顧客一覧_7月以降完全ユニークではない!$C:$C,"<"&DATE(2027,3,1), [1]流入チャネル別顧客一覧_7月以降完全ユニークではない!$S:$S,">="&EOMONTH(AK$3,-1)+1, [1]流入チャネル別顧客一覧_7月以降完全ユニークではない!$S:$S,"<"&EOMONTH(AK$3,0)+1 ) -> 0 | AL9: =SUM(E9:M9) -> 9 | AM9: =SUM(N9:Y9) -> 45 | AN9: =SUM(Z9:AK9) -> 8
A10: SQL率（SQL/MQL） | B10: - | C10: - | D10: - | E10: - | F10: - | G10: - | H10: =IF(H9=0,"0%",H9/H5) -> 0% | I10: =IF(I9=0,"0%",I9/I5) -> 0.14285714 | J10: =IF(J9=0,"0%",J9/J5) -> 0.2 | K10: =IF(K9=0,"0%",K9/K5) -> 0% | L10: =IF(L9=0,"0%",L9/L5) -> 0.125 | M10: =IF(M9=0,"0%",M9/M5) -> 0.055555556 | N10: =IF(N9=0,"0%",N9/N5) -> 0.060606061 | O10: =IF(O9=0,"0%",O9/O5) -> 0.25 | ... AN10: =IF(AN9=0,"0%",AN9/AN5) -> 0.094117647
A11: 受注 | B11: - | C11: - | D11: - | E11: - | F11: - | G11: - | H11: 0 | I11: 0 | J11: 0 | K11: 0 | L11: 1 | M11: 0 | N11: =COUNTIFS( [1]流入チャネル別顧客一覧_7月以降完全ユニークではない!$T:$T,">="&EOMONTH(N$3,-1)+1, [1]流入チャネル別顧客一覧_7月以降完全ユニークではない!$T:$T,"<"&EOMONTH(N$3,0)+1 ) -> 0 | O11: =COUNTIFS( [1]流入チャネル別顧客一覧_7月以降完全ユニークではない!$T:$T,">="&EOMONTH(O$3,-1)+1, [1]流入チャネル別顧客一覧_7月以降完全ユニークではない!$T:$T,"<"&EOMONTH(O$3,0)+1 ) -> 0 | P11: =COUNTIFS( [1]流入チャネル別顧客一覧_7月以降完全ユニークではない!$T:$T,">="&EOMONTH(P$3,-1)+1, [1]流入チャネル別顧客一覧_7月以降完全ユニークではない!$T:$T,"<"&EOMONTH(P$3,0)+1 ) -> 1 | Q11: =COUNTIFS( [1]流入チャネル別顧客一覧_7月以降完全ユニークではない!$T:$T,">="&EOMONTH(Q$3,-1)+1, [1]流入チャネル別顧客一覧_7月以降完全ユニークではない!$T:$T,"<"&EOMONTH(Q$3,0)+1 ) -> 0 | R11: =COUNTIFS( [1]流入チャネル別顧客一覧_7月以降完全ユニークではない!$T:$T,">="&EOMONTH(R$3,-1)+1, [1]流入チャネル別顧客一覧_7月以降完全ユニークではない!$T:$T,"<"&EOMONTH(R$3,0)+1 ) -> 0 | S11: =COUNTIFS( [1]流入チャネル別顧客一覧_7月以降完全ユニークではない!$T:$T,">="&EOMONTH(S$3,-1)+1, [1]流入チャネル別顧客一覧_7月以降完全ユニークではない!$T:$T,"<"&EOMONTH(S$3,0)+1 ) -> 0 | T11: =COUNTIFS( [1]流入チャネル別顧客一覧_7月以降完全ユニークではない!$T:$T,">="&EOMONTH(T$3,-1)+1, [1]流入チャネル別顧客一覧_7月以降完全ユニークではない!$T:$T,"<"&EOMONTH(T$3,0)+1 ) -> 2 | U11: =COUNTIFS( [1]流入チャネル別顧客一覧_7月以降完全ユニークではない!$T:$T,">="&EOMONTH(U$3,-1)+1, [1]流入チャネル別顧客一覧_7月以降完全ユニークではない!$T:$T,"<"&EOMONTH(U$3,0)+1 ) -> 0 | ... AK11: =COUNTIFS( [1]流入チャネル別顧客一覧_7月以降完全ユニークではない!$T:$T,">="&EOMONTH(AK$3,-1)+1, [1]流入チャネル別顧客一覧_7月以降完全ユニークではない!$T:$T,"<"&EOMONTH(AK$3,0)+1 ) -> 0 | AL11: =SUM(E11:M11) -> 1 | AM11: =SUM(N11:Y11) -> 6 | AN11: =SUM(Z11:AK11) -> 0
A12: 受注率（受注/MQL） | B12: - | C12: - | D12: - | E12: - | F12: - | G12: - | H12: =IF(H11=0,"0%",H11/H5) -> 0% | I12: =IF(I11=0,"0%",I11/I5) -> 0% | J12: =IF(J11=0,"0%",J11/J5) -> 0% | K12: =IF(K11=0,"0%",K11/K5) -> 0% | L12: =IF(L11=0,"0%",L11/L5) -> 0.0625 | M12: =IF(M11=0,"0%",M11/M5) -> 0% | N12: =IF(N11=0,"0%",N11/N5) -> 0% | O12: =IF(O11=0,"0%",O11/O5) -> 0% | ... AN12: =IF(AN11=0,"0%",AN11/AN5) -> 0%
A13: MAL目標 | B13: 269 | C13: 349 | D13: 404 | E13: 454 | F13: 504 | G13: 564 | H13: 614 | I13: 664 | J13: 724 | K13: 874 | L13: 924 | M13: 924 | Z13: =$AN13/12 -> 3302.1667 | AA13: =$AN13/12 -> 3302.1667 | AB13: =$AN13/12 -> 3302.1667 | AC13: =$AN13/12 -> 3302.1667 | AD13: =$AN13/12 -> 3302.1667 | AE13: =$AN13/12 -> 3302.1667 | AF13: =$AN13/12 -> 3302.1667 | AG13: =$AN13/12 -> 3302.1667 | ... AK13: =$AN13/12 -> 3302.1667 | AN13: 39626
A14: MAL目標達成率 | H14: =IF(H13=0,"0%",H4/H13) -> 0.21009772 | I14: =IF(I13=0,"0%",I4/I13) -> 1.371988 | J14: =IF(J13=0,"0%",J4/J13) -> 2.8729282 | K14: =IF(K13=0,"0%",K4/K13) -> 1.701373 | L14: =IF(L13=0,"0%",L4/L13) -> 3.4491342 | M14: =IF(M13=0,"0%",M4/M13) -> 1.9177489 | N14: =IF(N13=0,"0%",N4/N13) -> 0% | O14: =IF(O13=0,"0%",O4/O13) -> 0% | ... Y14: =IF(Y13=0,"0%",Y4/Y13) -> 0% | Z14: =SUM($Z4:Z4)/SUM($Z13:Z13) -> 0.91485388 | AA14: =SUM($Z4:AA4)/SUM($Z13:AA13) -> 0.93862615 | AB14: =SUM($Z4:AB4)/SUM($Z13:AB13) -> 0.89214152 | AC14: =SUM($Z4:AC4)/SUM($Z13:AC13) -> 0.99472569 | AD14: =SUM($Z4:AD4)/SUM($Z13:AD13) -> 0.79578055 | AE14: =SUM($Z4:AE4)/SUM($Z13:AE13) -> 0.66315046 | AF14: =SUM($Z4:AF4)/SUM($Z13:AF13) -> 0.56841468 | AG14: =SUM($Z4:AG4)/SUM($Z13:AG13) -> 0.49736284 | ... AK14: =SUM($Z4:AK4)/SUM($Z13:AK13) -> 0.33157523 | AL14: =IF(AL13=0,"0%",AL4/AL13) -> 0% | AM14: =IF(AM13=0,"0%",AM4/AM13) -> 0% | AN14: =IF(AN13=0,"0%",AN4/AN13) -> 0.33157523
A15: MQL目標 | B15: 3 | C15: 4 | D15: 4 | E15: 4 | F15: 4 | G15: 4 | H15: 5 | I15: 5 | J15: 5 | K15: 6 | L15: 7 | M15: 7 | Z15: =$AN15/12 -> 25 | AA15: =$AN15/12 -> 25 | AB15: =$AN15/12 -> 25 | AC15: =$AN15/12 -> 25 | AD15: =$AN15/12 -> 25 | AE15: =$AN15/12 -> 25 | AF15: =$AN15/12 -> 25 | AG15: =$AN15/12 -> 25 | ... AK15: =$AN15/12 -> 25 | AN15: 300
A16: MQL目標達成率 | H16: =IF(H15=0,"0%",H5/H15) -> 0.6 | I16: =IF(I15=0,"0%",I5/I15) -> 1.4 | J16: =IF(J15=0,"0%",J5/J15) -> 5 | K16: =IF(K15=0,"0%",K5/K15) -> 1.6666667 | L16: =IF(L15=0,"0%",L5/L15) -> 2.2857143 | M16: =IF(M15=0,"0%",M5/M15) -> 2.5714286 | N16: =IF(N15=0,"0%",N5/N15) -> 0% | O16: =IF(O15=0,"0%",O5/O15) -> 0% | ... Y16: =IF(Y15=0,"0%",Y5/Y15) -> 0% | Z16: =SUM($Z5:Z5)/SUM($Z15:Z15) -> 0.32 | AA16: =SUM($Z5:AA5)/SUM($Z15:AA15) -> 0.38 | AB16: =SUM($Z5:AB5)/SUM($Z15:AB15) -> 0.84 | AC16: =SUM($Z5:AC5)/SUM($Z15:AC15) -> 0.85 | AD16: =SUM($Z5:AD5)/SUM($Z15:AD15) -> 0.68 | AE16: =SUM($Z5:AE5)/SUM($Z15:AE15) -> 0.56666667 | AF16: =SUM($Z5:AF5)/SUM($Z15:AF15) -> 0.48571429 | AG16: =SUM($Z5:AG5)/SUM($Z15:AG15) -> 0.425 | ... AL16: =SUM($Z5:AL5)/SUM($Z15:AL15) -> 0.54666667 | AM16: =IF(AM15=0,"0%",AM5/AM15) -> 0% | AN16: =IF(AN15=0,"0%",AN5/AN15) -> 0.28333333
A17: MQL目標（昨年実績120％） | N17: {=ROUNDUP(SUM(($H$5:$M$5)*1.2)/12,0)} -> 8 | O17: {=ROUNDUP(SUM(($H$5:$M$5)*1.2)/12,0)} -> 8 | P17: {=ROUNDUP(SUM(($H$5:$M$5)*1.2)/12,0)} -> 8 | Q17: {=ROUNDUP(SUM(($H$5:$M$5)*1.2)/12,0)} -> 8 | R17: {=ROUNDUP(SUM(($H$5:$M$5)*1.2)/12,0)} -> 8 | S17: {=ROUNDUP(SUM(($H$5:$M$5)*1.2)/12,0)} -> 8 | T17: {=ROUNDUP(SUM(($H$5:$M$5)*1.2)/12,0)} -> 8 | U17: {=ROUNDUP(SUM(($H$5:$M$5)*1.2)/12,0)} -> 8 | ... Y17: {=ROUNDUP(SUM(($H$5:$M$5)*1.2)/12,0)} -> 8 | AN17: =SUM(Z17:AK17) -> 0
A18: MQL目標（KWポテンシャル） | N18: =8.9/12 -> 0.74166667 | O18: =8.9/12 -> 0.74166667 | P18: =8.9/12 -> 0.74166667 | Q18: =8.9/12 -> 0.74166667 | R18: =8.9/12 -> 0.74166667 | S18: =8.9/12 -> 0.74166667 | T18: =8.9/12 -> 0.74166667 | U18: =8.9/12 -> 0.74166667 | ... Y18: =8.9/12 -> 0.74166667 | AN18: =SUM(Z18:AK18) -> 0
A19: MQL目標（今年度利益目標111%） | N19: 24.2 | O19: 24.2 | P19: 24.2 | Q19: 24.2 | R19: 24.2 | S19: 24.2 | T19: 24.2 | U19: 24.2 | V19: 24.2 | W19: 24.2 | X19: 24.2 | Y19: 24.2 | AN19: =SUM(Z19:AK19) -> 0
A20: MQL目標（平均） | N20: =AVERAGE(N17:N19) -> 10.980556 | O20: =AVERAGE(O17:O19) -> 10.980556 | P20: =AVERAGE(P17:P19) -> 10.980556 | Q20: =AVERAGE(Q17:Q19) -> 10.980556 | R20: =AVERAGE(R17:R19) -> 10.980556 | S20: =AVERAGE(S17:S19) -> 10.980556 | T20: =AVERAGE(T17:T19) -> 10.980556 | U20: =AVERAGE(U17:U19) -> 10.980556 | ... Y20: =AVERAGE(Y17:Y19) -> 10.980556 | AN20: =SUM(Z20:AK20) -> 0
A21: SAL目標 | B21: 1.3 | C21: 2.3 | D21: 3 | E21: 3.4 | F21: 3.9 | G21: 4.3 | H21: 4.6 | I21: 4.9 | J21: 5.2 | K21: 6.2 | L21: 6.2 | M21: 6.2 | AN21: =SUM(Z21:AK21) -> 0
A22: SQL目標 | B22: 0.5 | C22: 0.8 | D22: 0.9 | E22: 1.1 | F22: 1.2 | G22: 1.3 | H22: 1.4 | I22: 1.5 | J22: 1.6 | K22: 1.9 | L22: 1.9 | M22: 1.9 | Z22: =$AN22/12 -> 5 | AA22: =$AN22/12 -> 5 | AB22: =$AN22/12 -> 5 | AC22: =$AN22/12 -> 5 | AD22: =$AN22/12 -> 5 | AE22: =$AN22/12 -> 5 | AF22: =$AN22/12 -> 5 | AG22: =$AN22/12 -> 5 | ... AK22: =$AN22/12 -> 5 | AN22: 60
A23: SQL目標達成率 | H23: =IF(H15=0,"0%",H9/H22) -> 0 | I23: =IF(I15=0,"0%",I9/I22) -> 0.66666667 | J23: =IF(J15=0,"0%",J9/J22) -> 3.125 | K23: =IF(K15=0,"0%",K9/K22) -> 0 | L23: =IF(L15=0,"0%",L9/L22) -> 1.0526316 | M23: =IF(M15=0,"0%",M9/M22) -> 0.52631579 | N23: =IF(N15=0,"0%",N9/N22) -> 0% | O23: =IF(O15=0,"0%",O9/O22) -> 0% | ... Y23: =IF(Y15=0,"0%",Y9/Y22) -> 0% | Z23: =SUM($Z9:Z9)/SUM($Z22:Z22) -> 0 | AA23: =SUM($Z9:AA9)/SUM($Z22:AA22) -> 0.1 | AB23: =SUM($Z9:AB9)/SUM($Z22:AB22) -> 0.2 | AC23: =SUM($Z9:AC9)/SUM($Z22:AC22) -> 0.4 | AD23: =SUM($Z9:AD9)/SUM($Z22:AD22) -> 0.32 | AE23: =SUM($Z9:AE9)/SUM($Z22:AE22) -> 0.26666667 | AF23: =SUM($Z9:AF9)/SUM($Z22:AF22) -> 0.22857143 | AG23: =SUM($Z9:AG9)/SUM($Z22:AG22) -> 0.2 | ... AK23: =SUM($Z9:AK9)/SUM($Z22:AK22) -> 0.13333333 | AL23: =IF(AL22=0,"0%",AL9/AL22) -> 0% | AM23: =IF(AM22=0,"0%",AM9/AM22) -> 0% | AN23: =IF(AN22=0,"0%",AN9/AN22) -> 0.13333333
A24: SQL目標（昨年実績120％） | N24: {=ROUNDUP(SUM(($H$9:$M$9)*1.2)/12,0)} -> 1 | O24: {=ROUNDUP(SUM(($H$9:$M$9)*1.2)/12,0)} -> 1 | P24: {=ROUNDUP(SUM(($H$9:$M$9)*1.2)/12,0)} -> 1 | Q24: {=ROUNDUP(SUM(($H$9:$M$9)*1.2)/12,0)} -> 1 | R24: {=ROUNDUP(SUM(($H$9:$M$9)*1.2)/12,0)} -> 1 | S24: {=ROUNDUP(SUM(($H$9:$M$9)*1.2)/12,0)} -> 1 | T24: {=ROUNDUP(SUM(($H$9:$M$9)*1.2)/12,0)} -> 1 | U24: {=ROUNDUP(SUM(($H$9:$M$9)*1.2)/12,0)} -> 1 | ... Y24: {=ROUNDUP(SUM(($H$9:$M$9)*1.2)/12,0)} -> 1
A25: SQL目標（KWポテンシャル） | N25: =N18*0.038*1.2 -> 0.03382 | O25: =O18*0.038*1.2 -> 0.03382 | P25: =P18*0.038*1.2 -> 0.03382 | Q25: =Q18*0.038*1.2 -> 0.03382 | R25: =R18*0.038*1.2 -> 0.03382 | S25: =S18*0.038*1.2 -> 0.03382 | T25: =T18*0.038*1.2 -> 0.03382 | U25: =U18*0.038*1.2 -> 0.03382 | ... Y25: =Y18*0.038*1.2 -> 0.03382
A26: SQL目標（今年度利益目標111%） | N26: =ROUNDUP(14.5/12,0) -> 2 | O26: =ROUNDUP(14.5/12,0) -> 2 | P26: =ROUNDUP(14.5/12,0) -> 2 | Q26: =ROUNDUP(14.5/12,0) -> 2 | R26: =ROUNDUP(14.5/12,0) -> 2 | S26: =ROUNDUP(14.5/12,0) -> 2 | T26: =ROUNDUP(14.5/12,0) -> 2 | U26: =ROUNDUP(14.5/12,0) -> 2 | ... Y26: =ROUNDUP(14.5/12,0) -> 2
A27: SQL目標（平均） | N27: =AVERAGE(N24:N26) -> 1.0112733 | O27: =AVERAGE(O24:O26) -> 1.0112733 | P27: =AVERAGE(P24:P26) -> 1.0112733 | Q27: =AVERAGE(Q24:Q26) -> 1.0112733 | R27: =AVERAGE(R24:R26) -> 1.0112733 | S27: =AVERAGE(S24:S26) -> 1.0112733 | T27: =AVERAGE(T24:T26) -> 1.0112733 | U27: =AVERAGE(U24:U26) -> 1.0112733 | ... Y27: =AVERAGE(Y24:Y26) -> 1.0112733
A28: 予算（予定） | N28: 1287500 | O28: 1287500 | P28: 1175000 | Q28: 1175000 | R28: 1175000 | S28: 1175000
A29: 予算（実績）合計 | B29: =SUM(#REF!,#REF!,#REF!) -> #REF! | C29: =SUM(#REF!,#REF!,#REF!) -> #REF! | D29: =SUM(#REF!,#REF!,#REF!) -> #REF! | E29: =SUM(#REF!,#REF!,#REF!) -> #REF! | F29: =SUM(#REF!,#REF!,#REF!) -> #REF! | G29: =SUM(#REF!,#REF!,#REF!) -> #REF! | H29: =SUM(#REF!,#REF!,#REF!) -> #REF! | I29: =SUM(#REF!,#REF!,#REF!) -> #REF! | ... M29: =SUM(#REF!,#REF!,#REF!) -> #REF! | N29: =SUM(N30:N37) -> 730614 | O29: =SUM(O30:O37) -> 904536 | P29: =SUM(P30:P37) -> 575477 | Q29: =SUM(Q30:Q37) -> 789410 | R29: =SUM(R30:R37) -> 654768 | S29: =SUM(S30:S37) -> 539796 | T29: =SUM(T30:T37) -> 484185 | U29: =SUM(U30:U37) -> 595988 | ... AK29: =SUM(AK30:AK37) -> 255000 | AL29: =SUM(B29:M29) -> #REF! | AM29: =SUM(N29:Y29) -> 8483081 | AN29: =SUM(Z29:AK29) -> 5333751
A30: 予算（実績）コラム | N30: ='[2]2025'!Z$84 -> 0 | O30: ='[2]2025'!AA$84 -> 220000 | P30: ='[2]2025'!AB$84 -> 0 | Q30: ='[2]2025'!AC$84 -> 220000 | R30: ='[2]2025'!AD$84 -> 55000 | S30: ='[2]2025'!AE$84 -> 0 | T30: ='[2]2025'!AF$84 -> 0 | U30: ='[2]2025'!AG$84 -> 110000 | ... Y30: ='[2]2025'!AK$84 -> 110000 | Z30: ='[2]2026'!F$23 -> 356000 | AA30: ='[2]2026'!G$23 -> 78000 | AB30: ='[2]2026'!H$23 -> 0 | AC30: ='[2]2026'!I$23 -> 0 | AD30: ='[2]2026'!J$23 -> 0 | AE30: ='[2]2026'!K$23 -> 0 | AF30: ='[2]2026'!L$23 -> 0 | AG30: ='[2]2026'!M$23 -> 0 | ... AK30: ='[2]2026'!Q$23 -> 0 | AM30: =SUM(N30:Y30) -> 1045000 | AN30: =SUM(Z30:AK30) -> 434000
A31: 予算（実績）メルマガ | N31: ='[2]2025'!Z$139 -> 90000 | O31: ='[2]2025'!AA$139 -> 30000 | P31: ='[2]2025'!AB$139 -> 30000 | Q31: ='[2]2025'!AC$139 -> 30000 | R31: ='[2]2025'!AD$139 -> 60000 | S31: ='[2]2025'!AE$139 -> 30000 | T31: ='[2]2025'!AF$139 -> 0 | U31: ='[2]2025'!AG$139 -> 0 | ... Y31: ='[2]2025'!AK$139 -> 105000 | Z31: ='[2]2026'!F$90 -> 75000 | AA31: ='[2]2026'!G$90 -> 43000 | AB31: ='[2]2026'!H$90 -> 73000 | AC31: ='[2]2026'!I$90 -> 0 | AD31: ='[2]2026'!J$90 -> 0 | AE31: ='[2]2026'!K$90 -> 0 | AF31: ='[2]2026'!L$90 -> 0 | AG31: ='[2]2026'!M$90 -> 0 | ... AK31: ='[2]2026'!Q$90 -> 0 | AM31: =SUM(N31:Y31) -> 450000 | AN31: =SUM(Z31:AK31) -> 191000
A32: 予算（実績）WP | N32: ='[2]2025'!Z$112 -> 0 | O32: ='[2]2025'!AA$112 -> 0 | P32: ='[2]2025'!AB$112 -> 0 | Q32: ='[2]2025'!AC$112 -> 0 | R32: ='[2]2025'!AD$112 -> 0 | S32: ='[2]2025'!AE$112 -> 0 | T32: ='[2]2025'!AF$112 -> 0 | U32: ='[2]2025'!AG$112 -> 0 | ... Y32: ='[2]2025'!AK$112 -> 0 | Z32: ='[2]2026'!F$58 -> 0 | AA32: ='[2]2026'!G$58 -> 0 | AB32: ='[2]2026'!H$58 -> 500000 | AC32: ='[2]2026'!I$58 -> 0 | AD32: ='[2]2026'!J$58 -> 0 | AE32: ='[2]2026'!K$58 -> 0 | AF32: ='[2]2026'!L$58 -> 0 | AG32: ='[2]2026'!M$58 -> 0 | ... AK32: ='[2]2026'!Q$58 -> 0 | AM32: =SUM(N32:Y32) -> 0 | AN32: =SUM(Z32:AK32) -> 500000
A33: 予算（実績）事例 | N33: ='[2]2025'!Z$161 -> 0 | O33: ='[2]2025'!AA$161 -> 10000 | P33: ='[2]2025'!AB$161 -> 20000 | Q33: ='[2]2025'!AC$161 -> 10000 | R33: ='[2]2025'!AD$161 -> 10000 | S33: ='[2]2025'!AE$161 -> 0 | T33: ='[2]2025'!AF$161 -> 0 | U33: ='[2]2025'!AG$161 -> 0 | ... Y33: ='[2]2025'!AK$161 -> 0 | Z33: ='[2]2026'!F$113 -> 355000 | AA33: ='[2]2026'!G$113 -> 0 | AB33: ='[2]2026'!H$113 -> 0 | AC33: ='[2]2026'!I$113 -> 0 | AD33: ='[2]2026'!J$113 -> 0 | AE33: ='[2]2026'!K$113 -> 0 | AF33: ='[2]2026'!L$113 -> 0 | AG33: ='[2]2026'!M$113 -> 0 | ... AK33: ='[2]2026'!Q$113 -> 0 | AM33: =SUM(N33:Y33) -> 760000 | AN33: =SUM(Z33:AK33) -> 355000
A34: 予算（実績）広告 | N34: 153114 | O34: 157036 | P34: 150477 | Q34: 154410 | R34: 154768 | S34: 134796 | T34: 229185 | U34: 230988 | V34: 236641 | W34: 199267 | X34: 217467 | Y34: 204932 | Z34: 137479 | AA34: 97826 | AB34: 0 | AC34: =58446+500000 -> 558446 | AM34: =SUM(N34:Z34) -> 2360560 | AN34: =SUM(Z34:AK34) -> 793751
A35: 予算（実績）Web運用 | N35: 0 | O35: 0 | P35: 0 | Q35: 0 | R35: 0 | S35: 0 | T35: 55000 | U35: 55000 | V35: 55000 | W35: 55000 | X35: 55000 | Y35: 55000 | Z35: 55000 | AA35: 55000 | AB35: 55000 | AC35: 55000 | AD35: 55000 | AE35: 55000 | AF35: 55000 | AG35: 55000 | AH35: 55000 | AI35: 55000 | AJ35: 55000 | AK35: 55000 | AM35: =SUM(N35:Y35) -> 330000 | AN35: =SUM(Z35:AK35) -> 660000
A36: 予算（実績）コンサル | N36: 487500 | O36: 487500 | P36: 375000 | Q36: 375000 | R36: 375000 | S36: 375000 | T36: 200000 | U36: 200000 | V36: 200000 | W36: 200000 | X36: 200000 | Y36: 200000 | Z36: 200000 | AA36: 200000 | AB36: 200000 | AC36: 200000 | AD36: 200000 | AE36: 200000 | AF36: 200000 | AG36: 200000 | AH36: 200000 | AI36: 200000 | AJ36: 200000 | AK36: 200000 | AM36: =SUM(N36:Y36) -> 3675000 | AN36: =SUM(Z36:AK36) -> 2400000
A37: 予算（実績）その他 | N37: 0 | O37: 0 | P37: 0 | Q37: 0 | R37: 0 | S37: 0 | T37: 0 | U37: 0 | V37: 0 | W37: 0 | X37: 0 | Y37: 0 | Z37: 0 | AA37: 0 | AB37: 0 | AC37: 0 | AD37: 0 | AE37: 0 | AF37: 0 | AG37: 0 | AH37: 0 | AI37: 0 | AJ37: 0 | AK37: 0 | AM37: =SUM(N37:Y37) -> 0 | AN37: =SUM(Z37:AK37) -> 0
A38: MQL単価 | B38: =IFERROR(B$29/B58,"") | C38: =IFERROR(C$29/C58,"") | D38: =IFERROR(D$29/D58,"") | E38: =IFERROR(E$29/E58,"") | F38: =IFERROR(F$29/F58,"") | G38: =IFERROR(G$29/G58,"") | H38: =IFERROR(H$29/H58,"") | I38: =IFERROR(I$29/I58,"") | ... M38: =IFERROR(M$29/M58,"") | N38: =IF(N5=0,0,N$29/N5) -> 22139.818 | O38: =IF(O5=0,0,O$29/O5) -> 45226.8 | P38: =IF(P5=0,0,P$29/P5) -> 44267.462 | Q38: =IF(Q5=0,0,Q$29/Q5) -> 52627.333 | R38: =IF(R5=0,0,R$29/R5) -> 14881.091 | S38: =IF(S5=0,0,S$29/S5) -> 18613.655 | T38: =IF(T5=0,0,$N$29/T5) -> 24353.8 | U38: =IF(U5=0,0,$N$29/U5) -> 38453.368 | V38: =IF(V5=0,0,$N$29/V5) -> 31765.826 | W38: =IF(W5=0,0,$N$29/W5) -> 52186.714 | X38: =IF(X5=0,0,$N$29/X5) -> 56201.077 | Y38: =IF(Y5=0,0,$N$29/Y5) -> 56201.077 | Z38: =IF(Z5=0,0,$N$29/Z5) -> 91326.75 | AA38: =IF(AA5=0,0,$N$29/AA5) -> 66419.455 | ... AL38: =IF(AL5=0,0,$N$29/AL5) -> 9248.2785 | AM38: =IF(AM5=0,0,AM$29/AM5) -> 31891.282 | AN38: =IF(AN5=0,0,AN$29/AN5) -> 62750.012
A39: SQL単価 | B39: =IFERROR(B$29/B9,"") | C39: =IFERROR(C$29/C9,"") | D39: =IFERROR(D$29/D9,"") | E39: =IFERROR(E$29/E9,"") | F39: =IFERROR(F$29/F9,"") | G39: =IFERROR(G$29/G9,"") | H39: =IFERROR(H$29/H9,"") | I39: =IFERROR(I$29/I9,"") | ... M39: =IFERROR(M$29/M9,"") | N39: =IF(N9=0,0,N$29/N9) -> 365307 | O39: =IF(O9=0,0,O$29/O9) -> 180907.2 | P39: =IF(P9=0,0,P$29/P9) -> 191825.67 | Q39: =IF(Q9=0,0,Q$29/Q9) -> 197352.5 | R39: =IF(R9=0,0,R$29/R9) -> 218256 | S39: =IF(S9=0,0,S$29/S9) -> 89966 | T39: =IF(T9=0,0,T$29/T9) -> 60523.125 | U39: =IF(U9=0,0,U$29/U9) -> 297994 | ... AK39: =IF(AK9=0,0,AK$29/AK9) -> 0 | AL39: =IF(AL9=0,0,$N$29/AL9) -> 81179.333 | AM39: =IF(AM9=0,0,AM$29/AM9) -> 188512.91 | AN39: =IF(AN9=0,0,AN$29/AN9) -> 666718.88
A40: 受注単価 | B40: =IFERROR(B$29/B11,"") | C40: =IFERROR(C$29/C11,"") | D40: =IFERROR(D$29/D11,"") | E40: =IFERROR(E$29/E11,"") | F40: =IFERROR(F$29/F11,"") | G40: =IFERROR(G$29/G11,"") | H40: =IFERROR(H$29/H11,"") | I40: =IFERROR(I$29/I11,"") | ... M40: =IFERROR(M$29/M11,"") | N40: =IF(N11=0,0,N$29/N11) -> 0 | O40: =IF(O11=0,0,O$29/O11) -> 0 | P40: =IF(P11=0,0,P$29/P11) -> 575477 | Q40: =IF(Q11=0,0,Q$29/Q11) -> 0 | R40: =IF(R11=0,0,R$29/R11) -> 0 | S40: =IF(S11=0,0,S$29/S11) -> 0 | T40: =IF(T11=0,0,T$29/T11) -> 242092.5 | U40: =IF(U11=0,0,U$29/U11) -> 0 | ... AK40: =IF(AK11=0,0,AK$29/AK11) -> 0 | AL40: =IF(AL11=0,0,$N$29/AL11) -> 730614 | AM40: =IF(AM11=0,0,AM$29/AM11) -> 1413846.8 | AN40: =IF(AN11=0,0,AN$29/AN11) -> 0
...

Sheet スクール
A2: リード実績（学生服） | B2: 2024年度 | N2: 2025年度 | Z2: 2026年度 | AC2: 7/1時点 | AL2: 合計 | AM2: 合計 | AN2: 合計
B3: 3月 | C3: 4月 | D3: 5月 | E3: 6月 | F3: 7月 | G3: 8月 | H3: 9月 | I3: 10月 | J3: 11月 | K3: 12月 | L3: 1月 | M3: 2月 | N3: 45717 | O3: 45748 | P3: 45778 | Q3: 45809 | R3: 45839 | S3: 45870 | T3: 45901 | U3: 45931 | V3: 45962 | W3: 45992 | X3: 46023 | Y3: 46054 | Z3: 46082 | AA3: 46113 | AB3: 46143 | AC3: 46174 | AD3: 46204 | AE3: 46235 | AF3: 46266 | AG3: 46296 | AH3: 46327 | AI3: 46357 | AJ3: 46388 | AK3: 46419 | AL3: 2024年度 | AM3: 2025年度 | AN3: 2026年度
A4: MAL | B4: - | C4: - | D4: - | E4: - | F4: - | G4: 59 | H4: 597 | I4: 1167 | J4: 1136 | K4: 1191 | L4: 1553 | M4: 1856 | N4: 1948 | O4: 1793 | P4: 1571 | Q4: 1823 | R4: 1907 | S4: 1415 | T4: 1474 | U4: 1499 | V4: 1791 | W4: 2637 | X4: 2227 | Y4: 3811 | Z4: 2465 | AA4: 2750 | AB4: 2887 | AC4: 2821 | AL4: =SUM(E4:M4) -> 7559 | AM4: =SUM(N4:Y4) -> 23896 | AN4: =SUM(Z4:AK4) -> 10923
A5: MQL | B5: - | C5: - | D5: - | E5: - | F5: - | G5: 0 | H5: 0 | I5: 3 | J5: 6 | K5: 4 | L5: 3 | M5: 3 | N5: =COUNTIFS( [3]流入チャネル別顧客一覧_ユニーク!$C:$C,">="&DATE(2025,3,1), [3]流入チャネル別顧客一覧_ユニーク!$C:$C,"<"&DATE(2026,3,1), [3]流入チャネル別顧客一覧_ユニーク!$C:$C,">="&N$3, [3]流入チャネル別顧客一覧_ユニーク!$C:$C,"<"&EDATE(N$3,1) ) -> 8 | O5: =COUNTIFS( [3]流入チャネル別顧客一覧_ユニーク!$C:$C,">="&DATE(2025,3,1), [3]流入チャネル別顧客一覧_ユニーク!$C:$C,"<"&DATE(2026,3,1), [3]流入チャネル別顧客一覧_ユニーク!$C:$C,">="&O$3, [3]流入チャネル別顧客一覧_ユニーク!$C:$C,"<"&EDATE(O$3,1) ) -> 4 | P5: =COUNTIFS( [3]流入チャネル別顧客一覧_ユニーク!$C:$C,">="&DATE(2025,3,1), [3]流入チャネル別顧客一覧_ユニーク!$C:$C,"<"&DATE(2026,3,1), [3]流入チャネル別顧客一覧_ユニーク!$C:$C,">="&P$3, [3]流入チャネル別顧客一覧_ユニーク!$C:$C,"<"&EDATE(P$3,1) ) -> 5 | Q5: =COUNTIFS( [3]流入チャネル別顧客一覧_ユニーク!$C:$C,">="&DATE(2025,3,1), [3]流入チャネル別顧客一覧_ユニーク!$C:$C,"<"&DATE(2026,3,1), [3]流入チャネル別顧客一覧_ユニーク!$C:$C,">="&Q$3, [3]流入チャネル別顧客一覧_ユニーク!$C:$C,"<"&EDATE(Q$3,1) ) -> 7 | R5: =COUNTIFS( [3]流入チャネル別顧客一覧_ユニーク!$C:$C,">="&DATE(2025,3,1), [3]流入チャネル別顧客一覧_ユニーク!$C:$C,"<"&DATE(2026,3,1), [3]流入チャネル別顧客一覧_ユニーク!$C:$C,">="&R$3, [3]流入チャネル別顧客一覧_ユニーク!$C:$C,"<"&EDATE(R$3,1) ) -> 0 | S5: =COUNTIFS( [3]流入チャネル別顧客一覧_ユニーク!$C:$C,">="&DATE(2025,3,1), [3]流入チャネル別顧客一覧_ユニーク!$C:$C,"<"&DATE(2026,3,1), [3]流入チャネル別顧客一覧_ユニーク!$C:$C,">="&S$3, [3]流入チャネル別顧客一覧_ユニーク!$C:$C,"<"&EDATE(S$3,1) ) -> 2 | T5: =COUNTIFS( [3]流入チャネル別顧客一覧_ユニーク!$C:$C,">="&DATE(2025,3,1), [3]流入チャネル別顧客一覧_ユニーク!$C:$C,"<"&DATE(2026,3,1), [3]流入チャネル別顧客一覧_ユニーク!$C:$C,">="&T$3, [3]流入チャネル別顧客一覧_ユニーク!$C:$C,"<"&EDATE(T$3,1) ) -> 3 | U5: =COUNTIFS( [3]流入チャネル別顧客一覧_ユニーク!$C:$C,">="&DATE(2025,3,1), [3]流入チャネル別顧客一覧_ユニーク!$C:$C,"<"&DATE(2026,3,1), [3]流入チャネル別顧客一覧_ユニーク!$C:$C,">="&U$3, [3]流入チャネル別顧客一覧_ユニーク!$C:$C,"<"&EDATE(U$3,1) ) -> 1 | ... Y5: =COUNTIFS( [3]流入チャネル別顧客一覧_ユニーク!$C:$C,">="&DATE(2025,3,1), [3]流入チャネル別顧客一覧_ユニーク!$C:$C,"<"&DATE(2026,3,1), [3]流入チャネル別顧客一覧_ユニーク!$C:$C,">="&Y$3, [3]流入チャネル別顧客一覧_ユニーク!$C:$C,"<"&EDATE(Y$3,1) ) -> 3 | Z5: =COUNTIFS( [3]流入チャネル別顧客一覧_ユニーク!$C:$C,">="&DATE(2026,3,1), [3]流入チャネル別顧客一覧_ユニーク!$C:$C,"<"&DATE(2027,3,1), [3]流入チャネル別顧客一覧_ユニーク!$C:$C,">="&Z$3, [3]流入チャネル別顧客一覧_ユニーク!$C:$C,"<"&EDATE(Z$3,1) ) -> 7 | AA5: =COUNTIFS( [3]流入チャネル別顧客一覧_ユニーク!$C:$C,">="&DATE(2026,3,1), [3]流入チャネル別顧客一覧_ユニーク!$C:$C,"<"&DATE(2027,3,1), [3]流入チャネル別顧客一覧_ユニーク!$C:$C,">="&AA$3, [3]流入チャネル別顧客一覧_ユニーク!$C:$C,"<"&EDATE(AA$3,1) ) -> 3 | AB5: =COUNTIFS( [3]流入チャネル別顧客一覧_ユニーク!$C:$C,">="&DATE(2026,3,1), [3]流入チャネル別顧客一覧_ユニーク!$C:$C,"<"&DATE(2027,3,1), [3]流入チャネル別顧客一覧_ユニーク!$C:$C,">="&AB$3, [3]流入チャネル別顧客一覧_ユニーク!$C:$C,"<"&EDATE(AB$3,1) ) -> 4 | AC5: =COUNTIFS( [3]流入チャネル別顧客一覧_ユニーク!$C:$C,">="&DATE(2026,3,1), [3]流入チャネル別顧客一覧_ユニーク!$C:$C,"<"&DATE(2027,3,1), [3]流入チャネル別顧客一覧_ユニーク!$C:$C,">="&AC$3, [3]流入チャネル別顧客一覧_ユニーク!$C:$C,"<"&EDATE(AC$3,1) ) -> 3 | AD5: =COUNTIFS( [3]流入チャネル別顧客一覧_ユニーク!$C:$C,">="&DATE(2026,3,1), [3]流入チャネル別顧客一覧_ユニーク!$C:$C,"<"&DATE(2027,3,1), [3]流入チャネル別顧客一覧_ユニーク!$C:$C,">="&AD$3, [3]流入チャネル別顧客一覧_ユニーク!$C:$C,"<"&EDATE(AD$3,1) ) -> 0 | AE5: =COUNTIFS( [3]流入チャネル別顧客一覧_ユニーク!$C:$C,">="&DATE(2026,3,1), [3]流入チャネル別顧客一覧_ユニーク!$C:$C,"<"&DATE(2027,3,1), [3]流入チャネル別顧客一覧_ユニーク!$C:$C,">="&AE$3, [3]流入チャネル別顧客一覧_ユニーク!$C:$C,"<"&EDATE(AE$3,1) ) -> 0 | AF5: =COUNTIFS( [3]流入チャネル別顧客一覧_ユニーク!$C:$C,">="&DATE(2026,3,1), [3]流入チャネル別顧客一覧_ユニーク!$C:$C,"<"&DATE(2027,3,1), [3]流入チャネル別顧客一覧_ユニーク!$C:$C,">="&AF$3, [3]流入チャネル別顧客一覧_ユニーク!$C:$C,"<"&EDATE(AF$3,1) ) -> 0 | AG5: =COUNTIFS( [3]流入チャネル別顧客一覧_ユニーク!$C:$C,">="&DATE(2026,3,1), [3]流入チャネル別顧客一覧_ユニーク!$C:$C,"<"&DATE(2027,3,1), [3]流入チャネル別顧客一覧_ユニーク!$C:$C,">="&AG$3, [3]流入チャネル別顧客一覧_ユニーク!$C:$C,"<"&EDATE(AG$3,1) ) -> 0 | ... AK5: =COUNTIFS( [3]流入チャネル別顧客一覧_ユニーク!$C:$C,">="&DATE(2026,3,1), [3]流入チャネル別顧客一覧_ユニーク!$C:$C,"<"&DATE(2027,3,1), [3]流入チャネル別顧客一覧_ユニーク!$C:$C,">="&AK$3, [3]流入チャネル別顧客一覧_ユニーク!$C:$C,"<"&EDATE(AK$3,1) ) -> 0 | AL5: =SUM(E5:M5) -> 19 | AM5: =SUM(N5:Y5) -> 39 | AN5: =SUM(Z5:AK5) -> 17
A6: MQL率（MQL/MAL） | N6: =N5/N4 -> 0.0041067762 | O6: =O5/O4 -> 0.0022308979 | P6: =P5/P4 -> 0.0031826862 | Q6: =Q5/Q4 -> 0.0038398245 | R6: =R5/R4 -> 0 | S6: =S5/S4 -> 0.0014134276 | T6: =T5/T4 -> 0.0020352782 | U6: =U5/U4 -> 0.00066711141 | ... AN6: =AN5/AN4 -> 0.001556349
A7: SAL | B7: - | C7: - | D7: - | E7: - | F7: - | G7: 0 | H7: 0 | I7: 0 | J7: 0 | K7: 0 | L7: 2 | M7: 0 | N7: =COUNTIFS( [3]流入チャネル別顧客一覧_ユニーク!$C:$C,">="&DATE(2025,3,1), [3]流入チャネル別顧客一覧_ユニーク!$C:$C,"<"&DATE(2026,3,1), [3]流入チャネル別顧客一覧_ユニーク!$R:$R,">="&EOMONTH(N$3,-1)+1, [3]流入チャネル別顧客一覧_ユニーク!$R:$R,"<"&EOMONTH(N$3,0)+1 ) -> 0 | O7: =COUNTIFS( [3]流入チャネル別顧客一覧_ユニーク!$C:$C,">="&DATE(2025,3,1), [3]流入チャネル別顧客一覧_ユニーク!$C:$C,"<"&DATE(2026,3,1), [3]流入チャネル別顧客一覧_ユニーク!$R:$R,">="&EOMONTH(O$3,-1)+1, [3]流入チャネル別顧客一覧_ユニーク!$R:$R,"<"&EOMONTH(O$3,0)+1 ) -> 0 | P7: =COUNTIFS( [3]流入チャネル別顧客一覧_ユニーク!$C:$C,">="&DATE(2025,3,1), [3]流入チャネル別顧客一覧_ユニーク!$C:$C,"<"&DATE(2026,3,1), [3]流入チャネル別顧客一覧_ユニーク!$R:$R,">="&EOMONTH(P$3,-1)+1, [3]流入チャネル別顧客一覧_ユニーク!$R:$R,"<"&EOMONTH(P$3,0)+1 ) -> 3 | Q7: =COUNTIFS( [3]流入チャネル別顧客一覧_ユニーク!$C:$C,">="&DATE(2025,3,1), [3]流入チャネル別顧客一覧_ユニーク!$C:$C,"<"&DATE(2026,3,1), [3]流入チャネル別顧客一覧_ユニーク!$R:$R,">="&EOMONTH(Q$3,-1)+1, [3]流入チャネル別顧客一覧_ユニーク!$R:$R,"<"&EOMONTH(Q$3,0)+1 ) -> 1 | R7: =COUNTIFS( [3]流入チャネル別顧客一覧_ユニーク!$C:$C,">="&DATE(2025,3,1), [3]流入チャネル別顧客一覧_ユニーク!$C:$C,"<"&DATE(2026,3,1), [3]流入チャネル別顧客一覧_ユニーク!$R:$R,">="&EOMONTH(R$3,-1)+1, [3]流入チャネル別顧客一覧_ユニーク!$R:$R,"<"&EOMONTH(R$3,0)+1 ) -> 0 | S7: =COUNTIFS( [3]流入チャネル別顧客一覧_ユニーク!$C:$C,">="&DATE(2025,3,1), [3]流入チャネル別顧客一覧_ユニーク!$C:$C,"<"&DATE(2026,3,1), [3]流入チャネル別顧客一覧_ユニーク!$R:$R,">="&EOMONTH(S$3,-1)+1, [3]流入チャネル別顧客一覧_ユニーク!$R:$R,"<"&EOMONTH(S$3,0)+1 ) -> 0 | T7: =COUNTIFS( [3]流入チャネル別顧客一覧_ユニーク!$C:$C,">="&DATE(2025,3,1), [3]流入チャネル別顧客一覧_ユニーク!$C:$C,"<"&DATE(2026,3,1), [3]流入チャネル別顧客一覧_ユニーク!$R:$R,">="&EOMONTH(T$3,-1)+1, [3]流入チャネル別顧客一覧_ユニーク!$R:$R,"<"&EOMONTH(T$3,0)+1 ) -> 0 | U7: =COUNTIFS( [3]流入チャネル別顧客一覧_ユニーク!$C:$C,">="&DATE(2025,3,1), [3]流入チャネル別顧客一覧_ユニーク!$C:$C,"<"&DATE(2026,3,1), [3]流入チャネル別顧客一覧_ユニーク!$R:$R,">="&EOMONTH(U$3,-1)+1, [3]流入チャネル別顧客一覧_ユニーク!$R:$R,"<"&EOMONTH(U$3,0)+1 ) -> 2 | ... Y7: =COUNTIFS( [3]流入チャネル別顧客一覧_ユニーク!$C:$C,">="&DATE(2025,3,1), [3]流入チャネル別顧客一覧_ユニーク!$C:$C,"<"&DATE(2026,3,1), [3]流入チャネル別顧客一覧_ユニーク!$R:$R,">="&EOMONTH(Y$3,-1)+1, [3]流入チャネル別顧客一覧_ユニーク!$R:$R,"<"&EOMONTH(Y$3,0)+1 ) -> 0 | Z7: =COUNTIFS( [3]流入チャネル別顧客一覧_ユニーク!$C:$C,">="&DATE(2026,3,1), [3]流入チャネル別顧客一覧_ユニーク!$C:$C,"<"&DATE(2027,3,1), [3]流入チャネル別顧客一覧_ユニーク!$R:$R,">="&EOMONTH(Z$3,-1)+1, [3]流入チャネル別顧客一覧_ユニーク!$R:$R,"<"&EOMONTH(Z$3,0)+1 ) -> 0 | AA7: =COUNTIFS( [3]流入チャネル別顧客一覧_ユニーク!$C:$C,">="&DATE(2026,3,1), [3]流入チャネル別顧客一覧_ユニーク!$C:$C,"<"&DATE(2027,3,1), [3]流入チャネル別顧客一覧_ユニーク!$R:$R,">="&EOMONTH(AA$3,-1)+1, [3]流入チャネル別顧客一覧_ユニーク!$R:$R,"<"&EOMONTH(AA$3,0)+1 ) -> 0 | AB7: =COUNTIFS( [3]流入チャネル別顧客一覧_ユニーク!$C:$C,">="&DATE(2026,3,1), [3]流入チャネル別顧客一覧_ユニーク!$C:$C,"<"&DATE(2027,3,1), [3]流入チャネル別顧客一覧_ユニーク!$R:$R,">="&EOMONTH(AB$3,-1)+1, [3]流入チャネル別顧客一覧_ユニーク!$R:$R,"<"&EOMONTH(AB$3,0)+1 ) -> 1 | AC7: =COUNTIFS( [3]流入チャネル別顧客一覧_ユニーク!$C:$C,">="&DATE(2026,3,1), [3]流入チャネル別顧客一覧_ユニーク!$C:$C,"<"&DATE(2027,3,1), [3]流入チャネル別顧客一覧_ユニーク!$R:$R,">="&EOMONTH(AC$3,-1)+1, [3]流入チャネル別顧客一覧_ユニーク!$R:$R,"<"&EOMONTH(AC$3,0)+1 ) -> 0 | AD7: =COUNTIFS( [3]流入チャネル別顧客一覧_ユニーク!$C:$C,">="&DATE(2026,3,1), [3]流入チャネル別顧客一覧_ユニーク!$C:$C,"<"&DATE(2027,3,1), [3]流入チャネル別顧客一覧_ユニーク!$R:$R,">="&EOMONTH(AD$3,-1)+1, [3]流入チャネル別顧客一覧_ユニーク!$R:$R,"<"&EOMONTH(AD$3,0)+1 ) -> 0 | AE7: =COUNTIFS( [3]流入チャネル別顧客一覧_ユニーク!$C:$C,">="&DATE(2026,3,1), [3]流入チャネル別顧客一覧_ユニーク!$C:$C,"<"&DATE(2027,3,1), [3]流入チャネル別顧客一覧_ユニーク!$R:$R,">="&EOMONTH(AE$3,-1)+1, [3]流入チャネル別顧客一覧_ユニーク!$R:$R,"<"&EOMONTH(AE$3,0)+1 ) -> 0 | AF7: =COUNTIFS( [3]流入チャネル別顧客一覧_ユニーク!$C:$C,">="&DATE(2026,3,1), [3]流入チャネル別顧客一覧_ユニーク!$C:$C,"<"&DATE(2027,3,1), [3]流入チャネル別顧客一覧_ユニーク!$R:$R,">="&EOMONTH(AF$3,-1)+1, [3]流入チャネル別顧客一覧_ユニーク!$R:$R,"<"&EOMONTH(AF$3,0)+1 ) -> 0 | AG7: =COUNTIFS( [3]流入チャネル別顧客一覧_ユニーク!$C:$C,">="&DATE(2026,3,1), [3]流入チャネル別顧客一覧_ユニーク!$C:$C,"<"&DATE(2027,3,1), [3]流入チャネル別顧客一覧_ユニーク!$R:$R,">="&EOMONTH(AG$3,-1)+1, [3]流入チャネル別顧客一覧_ユニーク!$R:$R,"<"&EOMONTH(AG$3,0)+1 ) -> 0 | ... AK7: =COUNTIFS( [3]流入チャネル別顧客一覧_ユニーク!$C:$C,">="&DATE(2026,3,1), [3]流入チャネル別顧客一覧_ユニーク!$C:$C,"<"&DATE(2027,3,1), [3]流入チャネル別顧客一覧_ユニーク!$R:$R,">="&EOMONTH(AK$3,-1)+1, [3]流入チャネル別顧客一覧_ユニーク!$R:$R,"<"&EOMONTH(AK$3,0)+1 ) -> 0 | AM7: =SUM(N7:Y7) -> 7 | AN7: =SUM(Z7:AK7) -> 1
A8: SAL率（SAL/MQL） | B8: - | C8: - | D8: - | E8: - | F8: - | G8: =IF(G7=0,"0%",G7/G5) -> 0% | H8: =IF(H7=0,"0%",H7/H5) -> 0% | I8: =IF(I7=0,"0%",I7/I5) -> 0% | J8: =IF(J7=0,"0%",J7/J5) -> 0% | K8: =IF(K7=0,"0%",K7/K5) -> 0% | L8: =IF(L7=0,"0%",L7/L5) -> 0.66666667 | M8: =IF(M7=0,"0%",M7/M5) -> 0% | N8: =IF(N7=0,"0%",N7/N5) -> 0% | ... AK8: =IF(AK7=0,"0%",AK7/AK5) -> 0% | AN8: =IF(AN7=0,"0%",AN7/AN5) -> 0.058823529
A9: SQL（案件化数） | B9: - | C9: - | D9: - | E9: - | F9: - | G9: 0 | H9: 0 | I9: 0 | J9: 0 | K9: 0 | L9: 0 | M9: 2 | N9: =COUNTIFS( [3]流入チャネル別顧客一覧_ユニーク!$C:$C,">="&DATE(2025,3,1), [3]流入チャネル別顧客一覧_ユニーク!$C:$C,"<"&DATE(2026,3,1), [3]流入チャネル別顧客一覧_ユニーク!$S:$S,">="&EOMONTH(N$3,-1)+1, [3]流入チャネル別顧客一覧_ユニーク!$S:$S,"<"&EOMONTH(N$3,0)+1 ) -> 0 | O9: =COUNTIFS( [3]流入チャネル別顧客一覧_ユニーク!$C:$C,">="&DATE(2025,3,1), [3]流入チャネル別顧客一覧_ユニーク!$C:$C,"<"&DATE(2026,3,1), [3]流入チャネル別顧客一覧_ユニーク!$S:$S,">="&EOMONTH(O$3,-1)+1, [3]流入チャネル別顧客一覧_ユニーク!$S:$S,"<"&EOMONTH(O$3,0)+1 ) -> 0 | P9: =COUNTIFS( [3]流入チャネル別顧客一覧_ユニーク!$C:$C,">="&DATE(2025,3,1), [3]流入チャネル別顧客一覧_ユニーク!$C:$C,"<"&DATE(2026,3,1), [3]流入チャネル別顧客一覧_ユニーク!$S:$S,">="&EOMONTH(P$3,-1)+1, [3]流入チャネル別顧客一覧_ユニーク!$S:$S,"<"&EOMONTH(P$3,0)+1 ) -> 3 | Q9: =COUNTIFS( [3]流入チャネル別顧客一覧_ユニーク!$C:$C,">="&DATE(2025,3,1), [3]流入チャネル別顧客一覧_ユニーク!$C:$C,"<"&DATE(2026,3,1), [3]流入チャネル別顧客一覧_ユニーク!$S:$S,">="&EOMONTH(Q$3,-1)+1, [3]流入チャネル別顧客一覧_ユニーク!$S:$S,"<"&EOMONTH(Q$3,0)+1 ) -> 0 | R9: =COUNTIFS( [3]流入チャネル別顧客一覧_ユニーク!$C:$C,">="&DATE(2025,3,1), [3]流入チャネル別顧客一覧_ユニーク!$C:$C,"<"&DATE(2026,3,1), [3]流入チャネル別顧客一覧_ユニーク!$S:$S,">="&EOMONTH(R$3,-1)+1, [3]流入チャネル別顧客一覧_ユニーク!$S:$S,"<"&EOMONTH(R$3,0)+1 ) -> 1 | S9: =COUNTIFS( [3]流入チャネル別顧客一覧_ユニーク!$C:$C,">="&DATE(2025,3,1), [3]流入チャネル別顧客一覧_ユニーク!$C:$C,"<"&DATE(2026,3,1), [3]流入チャネル別顧客一覧_ユニーク!$S:$S,">="&EOMONTH(S$3,-1)+1, [3]流入チャネル別顧客一覧_ユニーク!$S:$S,"<"&EOMONTH(S$3,0)+1 ) -> 0 | T9: =COUNTIFS( [3]流入チャネル別顧客一覧_ユニーク!$C:$C,">="&DATE(2025,3,1), [3]流入チャネル別顧客一覧_ユニーク!$C:$C,"<"&DATE(2026,3,1), [3]流入チャネル別顧客一覧_ユニーク!$S:$S,">="&EOMONTH(T$3,-1)+1, [3]流入チャネル別顧客一覧_ユニーク!$S:$S,"<"&EOMONTH(T$3,0)+1 ) -> 0 | U9: =COUNTIFS( [3]流入チャネル別顧客一覧_ユニーク!$C:$C,">="&DATE(2025,3,1), [3]流入チャネル別顧客一覧_ユニーク!$C:$C,"<"&DATE(2026,3,1), [3]流入チャネル別顧客一覧_ユニーク!$S:$S,">="&EOMONTH(U$3,-1)+1, [3]流入チャネル別顧客一覧_ユニーク!$S:$S,"<"&EOMONTH(U$3,0)+1 ) -> 0 | ... Y9: =COUNTIFS( [3]流入チャネル別顧客一覧_ユニーク!$C:$C,">="&DATE(2025,3,1), [3]流入チャネル別顧客一覧_ユニーク!$C:$C,"<"&DATE(2026,3,1), [3]流入チャネル別顧客一覧_ユニーク!$S:$S,">="&EOMONTH(Y$3,-1)+1, [3]流入チャネル別顧客一覧_ユニーク!$S:$S,"<"&EOMONTH(Y$3,0)+1 ) -> 1 | Z9: =COUNTIFS( [3]流入チャネル別顧客一覧_ユニーク!$C:$C,">="&DATE(2026,3,1), [3]流入チャネル別顧客一覧_ユニーク!$C:$C,"<"&DATE(2027,3,1), [3]流入チャネル別顧客一覧_ユニーク!$S:$S,">="&EOMONTH(Z$3,-1)+1, [3]流入チャネル別顧客一覧_ユニーク!$S:$S,"<"&EOMONTH(Z$3,0)+1 ) -> 0 | AA9: =COUNTIFS( [3]流入チャネル別顧客一覧_ユニーク!$C:$C,">="&DATE(2026,3,1), [3]流入チャネル別顧客一覧_ユニーク!$C:$C,"<"&DATE(2027,3,1), [3]流入チャネル別顧客一覧_ユニーク!$S:$S,">="&EOMONTH(AA$3,-1)+1, [3]流入チャネル別顧客一覧_ユニーク!$S:$S,"<"&EOMONTH(AA$3,0)+1 ) -> 0 | AB9: =COUNTIFS( [3]流入チャネル別顧客一覧_ユニーク!$C:$C,">="&DATE(2026,3,1), [3]流入チャネル別顧客一覧_ユニーク!$C:$C,"<"&DATE(2027,3,1), [3]流入チャネル別顧客一覧_ユニーク!$S:$S,">="&EOMONTH(AB$3,-1)+1, [3]流入チャネル別顧客一覧_ユニーク!$S:$S,"<"&EOMONTH(AB$3,0)+1 ) -> 0 | AC9: =COUNTIFS( [3]流入チャネル別顧客一覧_ユニーク!$C:$C,">="&DATE(2026,3,1), [3]流入チャネル別顧客一覧_ユニーク!$C:$C,"<"&DATE(2027,3,1), [3]流入チャネル別顧客一覧_ユニーク!$S:$S,">="&EOMONTH(AC$3,-1)+1, [3]流入チャネル別顧客一覧_ユニーク!$S:$S,"<"&EOMONTH(AC$3,0)+1 ) -> 0 | AD9: =COUNTIFS( [3]流入チャネル別顧客一覧_ユニーク!$C:$C,">="&DATE(2026,3,1), [3]流入チャネル別顧客一覧_ユニーク!$C:$C,"<"&DATE(2027,3,1), [3]流入チャネル別顧客一覧_ユニーク!$S:$S,">="&EOMONTH(AD$3,-1)+1, [3]流入チャネル別顧客一覧_ユニーク!$S:$S,"<"&EOMONTH(AD$3,0)+1 ) -> 0 | AE9: =COUNTIFS( [3]流入チャネル別顧客一覧_ユニーク!$C:$C,">="&DATE(2026,3,1), [3]流入チャネル別顧客一覧_ユニーク!$C:$C,"<"&DATE(2027,3,1), [3]流入チャネル別顧客一覧_ユニーク!$S:$S,">="&EOMONTH(AE$3,-1)+1, [3]流入チャネル別顧客一覧_ユニーク!$S:$S,"<"&EOMONTH(AE$3,0)+1 ) -> 0 | AF9: =COUNTIFS( [3]流入チャネル別顧客一覧_ユニーク!$C:$C,">="&DATE(2026,3,1), [3]流入チャネル別顧客一覧_ユニーク!$C:$C,"<"&DATE(2027,3,1), [3]流入チャネル別顧客一覧_ユニーク!$S:$S,">="&EOMONTH(AF$3,-1)+1, [3]流入チャネル別顧客一覧_ユニーク!$S:$S,"<"&EOMONTH(AF$3,0)+1 ) -> 0 | AG9: =COUNTIFS( [3]流入チャネル別顧客一覧_ユニーク!$C:$C,">="&DATE(2026,3,1), [3]流入チャネル別顧客一覧_ユニーク!$C:$C,"<"&DATE(2027,3,1), [3]流入チャネル別顧客一覧_ユニーク!$S:$S,">="&EOMONTH(AG$3,-1)+1, [3]流入チャネル別顧客一覧_ユニーク!$S:$S,"<"&EOMONTH(AG$3,0)+1 ) -> 0 | ... AK9: =COUNTIFS( [3]流入チャネル別顧客一覧_ユニーク!$C:$C,">="&DATE(2026,3,1), [3]流入チャネル別顧客一覧_ユニーク!$C:$C,"<"&DATE(2027,3,1), [3]流入チャネル別顧客一覧_ユニーク!$S:$S,">="&EOMONTH(AK$3,-1)+1, [3]流入チャネル別顧客一覧_ユニーク!$S:$S,"<"&EOMONTH(AK$3,0)+1 ) -> 0 | AL9: =SUM(E9:M9) -> 2 | AM9: =SUM(N9:Y9) -> 7 | AN9: =SUM(Z9:AK9) -> 0
A10: SQL率（SQL/MQL） | B10: - | C10: - | D10: - | E10: - | F10: - | G10: =IF(G9=0,"0%",G9/G5) -> 0% | H10: =IF(H9=0,"0%",H9/H5) -> 0% | I10: =IF(I9=0,"0%",I9/I5) -> 0% | J10: =IF(J9=0,"0%",J9/J5) -> 0% | K10: =IF(K9=0,"0%",K9/K5) -> 0% | L10: =IF(L9=0,"0%",L9/L5) -> 0% | M10: =IF(M9=0,"0%",M9/M5) -> 0.66666667 | N10: =IF(N9=0,"0%",N9/N5) -> 0% | ... AK10: =IF(AK9=0,"0%",AK9/AK5) -> 0% | AN10: =IF(AN9=0,"0%",AN9/AN5) -> 0%
A11: 受注 | B11: - | C11: - | D11: - | E11: - | F11: - | G11: 0 | H11: 0 | I11: 0 | J11: 0 | K11: 0 | L11: 0 | M11: 0 | N11: =COUNTIFS( [3]流入チャネル別顧客一覧_ユニーク!$T:$T,">="&EOMONTH(N$3,-1)+1, [3]流入チャネル別顧客一覧_ユニーク!$T:$T,"<"&EOMONTH(N$3,0)+1 ) -> 1 | O11: =COUNTIFS( [3]流入チャネル別顧客一覧_ユニーク!$T:$T,">="&EOMONTH(O$3,-1)+1, [3]流入チャネル別顧客一覧_ユニーク!$T:$T,"<"&EOMONTH(O$3,0)+1 ) -> 0 | P11: =COUNTIFS( [3]流入チャネル別顧客一覧_ユニーク!$T:$T,">="&EOMONTH(P$3,-1)+1, [3]流入チャネル別顧客一覧_ユニーク!$T:$T,"<"&EOMONTH(P$3,0)+1 ) -> 0 | Q11: =COUNTIFS( [3]流入チャネル別顧客一覧_ユニーク!$T:$T,">="&EOMONTH(Q$3,-1)+1, [3]流入チャネル別顧客一覧_ユニーク!$T:$T,"<"&EOMONTH(Q$3,0)+1 ) -> 0 | R11: =COUNTIFS( [3]流入チャネル別顧客一覧_ユニーク!$T:$T,">="&EOMONTH(R$3,-1)+1, [3]流入チャネル別顧客一覧_ユニーク!$T:$T,"<"&EOMONTH(R$3,0)+1 ) -> 0 | S11: =COUNTIFS( [3]流入チャネル別顧客一覧_ユニーク!$T:$T,">="&EOMONTH(S$3,-1)+1, [3]流入チャネル別顧客一覧_ユニーク!$T:$T,"<"&EOMONTH(S$3,0)+1 ) -> 0 | T11: =COUNTIFS( [3]流入チャネル別顧客一覧_ユニーク!$T:$T,">="&EOMONTH(T$3,-1)+1, [3]流入チャネル別顧客一覧_ユニーク!$T:$T,"<"&EOMONTH(T$3,0)+1 ) -> 1 | U11: =COUNTIFS( [3]流入チャネル別顧客一覧_ユニーク!$T:$T,">="&EOMONTH(U$3,-1)+1, [3]流入チャネル別顧客一覧_ユニーク!$T:$T,"<"&EOMONTH(U$3,0)+1 ) -> 0 | ... AK11: =COUNTIFS( [3]流入チャネル別顧客一覧_ユニーク!$T:$T,">="&EOMONTH(AK$3,-1)+1, [3]流入チャネル別顧客一覧_ユニーク!$T:$T,"<"&EOMONTH(AK$3,0)+1 ) -> 0 | AL11: =SUM(E11:M11) -> 0 | AM11: =SUM(N11:Y11) -> 2 | AN11: =SUM(Z11:AK11) -> 0
A12: 受注率（受注/MQL） | B12: - | C12: - | D12: - | E12: - | F12: - | G12: =IF(G11=0,"0%",G11/G5) -> 0% | H12: =IF(H11=0,"0%",H11/H5) -> 0% | I12: =IF(I11=0,"0%",I11/I5) -> 0% | J12: =IF(J11=0,"0%",J11/J5) -> 0% | K12: =IF(K11=0,"0%",K11/K5) -> 0% | L12: =IF(L11=0,"0%",L11/L5) -> 0% | M12: =IF(M11=0,"0%",M11/M5) -> 0% | N12: =IF(N11=0,"0%",N11/N5) -> 0.125 | ... AK12: =IF(AK11=0,"0%",AK11/AK5) -> 0%
A13: MAL目標 | B13: 269 | C13: 349 | D13: 404 | E13: 454 | F13: 504 | G13: 564 | H13: 614 | I13: 664 | J13: 724 | K13: 874 | L13: 924 | M13: 924 | Z13: =$AN13/12 -> 3574.1667 | AA13: =$AN13/12 -> 3574.1667 | AB13: =$AN13/12 -> 3574.1667 | AC13: =$AN13/12 -> 3574.1667 | AD13: =$AN13/12 -> 3574.1667 | AE13: =$AN13/12 -> 3574.1667 | AF13: =$AN13/12 -> 3574.1667 | AG13: =$AN13/12 -> 3574.1667 | ... AK13: =$AN13/12 -> 3574.1667 | AN13: 42890
A14: MAL目標達成率 | H14: =IF(H13=0,"0%",H4/H13) -> 0.9723127 | I14: =IF(I13=0,"0%",I4/I13) -> 1.7575301 | J14: =IF(J13=0,"0%",J4/J13) -> 1.5690608 | K14: =IF(K13=0,"0%",K4/K13) -> 1.3627002 | L14: =IF(L13=0,"0%",L4/L13) -> 1.6807359 | M14: =IF(M13=0,"0%",M4/M13) -> 2.008658 | N14: =IF(N13=0,"0%",N4/N13) -> 0% | O14: =IF(O13=0,"0%",O4/O13) -> 0% | ... Y14: =IF(Y13=0,"0%",Y4/Y13) -> 0% | Z14: =SUM($Z4:Z4)/SUM($Z13:Z13) -> 0.68967125 | AA14: =SUM($Z4:AA4)/SUM($Z13:AA13) -> 0.72954069 | AB14: =SUM($Z4:AB4)/SUM($Z13:AB13) -> 0.75560737 | AC14: =SUM($Z4:AC4)/SUM($Z13:AC13) -> 0.76402425 | AD14: =SUM($Z4:AD4)/SUM($Z13:AD13) -> 0.6112194 | AE14: =SUM($Z4:AE4)/SUM($Z13:AE13) -> 0.5093495 | AF14: =SUM($Z4:AF4)/SUM($Z13:AF13) -> 0.43658528 | AG14: =SUM($Z4:AG4)/SUM($Z13:AG13) -> 0.38201212 | ... AK14: =SUM($Z4:AK4)/SUM($Z13:AK13) -> 0.25467475 | AL14: =IF(AL13=0,"0%",AL4/AL13) -> 0% | AM14: =IF(AM13=0,"0%",AM4/AM13) -> 0% | AN14: =IF(AN13=0,"0%",AN4/AN13) -> 0.25467475
A15: MQL目標 | B15: 3 | C15: 4 | D15: 4 | E15: 4 | F15: 4 | G15: 4 | H15: 5 | I15: 5 | J15: 5 | K15: 6 | L15: 7 | M15: 7 | Z15: =$AN15/12 -> 5.8333333 | AA15: =$AN15/12 -> 5.8333333 | AB15: =$AN15/12 -> 5.8333333 | AC15: =$AN15/12 -> 5.8333333 | AD15: =$AN15/12 -> 5.8333333 | AE15: =$AN15/12 -> 5.8333333 | AF15: =$AN15/12 -> 5.8333333 | AG15: =$AN15/12 -> 5.8333333 | ... AK15: =$AN15/12 -> 5.8333333 | AN15: 70
A16: MQL目標達成率 | H16: =IF(H15=0,"0%",H5/H15) -> 0 | I16: =IF(I15=0,"0%",I5/I15) -> 0.6 | J16: =IF(J15=0,"0%",J5/J15) -> 1.2 | K16: =IF(K15=0,"0%",K5/K15) -> 0.66666667 | L16: =IF(L15=0,"0%",L5/L15) -> 0.42857143 | M16: =IF(M15=0,"0%",M5/M15) -> 0.42857143 | N16: =IF(N15=0,"0%",N5/N15) -> 0% | O16: =IF(O15=0,"0%",O5/O15) -> 0% | ... Y16: =IF(Y15=0,"0%",Y5/Y15) -> 0% | Z16: =SUM($Z5:Z5)/SUM($Z15:Z15) -> 1.2 | AA16: =SUM($Z5:AA5)/SUM($Z15:AA15) -> 0.85714286 | AB16: =SUM($Z5:AB5)/SUM($Z15:AB15) -> 0.8 | AC16: =SUM($Z5:AC5)/SUM($Z15:AC15) -> 0.72857143 | AD16: =SUM($Z5:AD5)/SUM($Z15:AD15) -> 0.58285714 | AE16: =SUM($Z5:AE5)/SUM($Z15:AE15) -> 0.48571429 | AF16: =SUM($Z5:AF5)/SUM($Z15:AF15) -> 0.41632653 | AG16: =SUM($Z5:AG5)/SUM($Z15:AG15) -> 0.36428571 | ... AK16: =SUM($Z5:AK5)/SUM($Z15:AK15) -> 0.24285714 | AL16: =IF(AL15=0,"0%",AL5/AL15) -> 0% | AM16: =IF(AM15=0,"0%",AM5/AM15) -> 0% | AN16: =IF(AN15=0,"0%",AN5/AN15) -> 0.24285714
A17: MQL目標（昨年実績120％） | N17: {=ROUNDUP(SUM(($G$5:$M$5)*1.2)/12,0)} -> 2 | O17: {=ROUNDUP(SUM(($G$5:$M$5)*1.2)/12,0)} -> 2 | P17: {=ROUNDUP(SUM(($G$5:$M$5)*1.2)/12,0)} -> 2 | Q17: {=ROUNDUP(SUM(($G$5:$M$5)*1.2)/12,0)} -> 2 | R17: {=ROUNDUP(SUM(($G$5:$M$5)*1.2)/12,0)} -> 2 | S17: {=ROUNDUP(SUM(($G$5:$M$5)*1.2)/12,0)} -> 2 | T17: {=ROUNDUP(SUM(($G$5:$M$5)*1.2)/12,0)} -> 2 | U17: {=ROUNDUP(SUM(($G$5:$M$5)*1.2)/12,0)} -> 2 | ... Y17: {=ROUNDUP(SUM(($G$5:$M$5)*1.2)/12,0)} -> 2
A18: MQL目標（KWポテンシャル） | N18: =13.44/12 -> 1.12 | O18: =13.44/12 -> 1.12 | P18: =13.44/12 -> 1.12 | Q18: =13.44/12 -> 1.12 | R18: =13.44/12 -> 1.12 | S18: =13.44/12 -> 1.12 | T18: =13.44/12 -> 1.12 | U18: =13.44/12 -> 1.12 | ... Y18: =13.44/12 -> 1.12
A19: MQL目標（今年度利益目標111%） | N19: 6.05 | O19: 6.05 | P19: 6.05 | Q19: 6.05 | R19: 6.05 | S19: 6.05 | T19: 6.05 | U19: 6.05 | V19: 6.05 | W19: 6.05 | X19: 6.05 | Y19: 6.05
A20: MQL目標（平均） | N20: =AVERAGE(N17:N19) -> 3.0566667 | O20: =AVERAGE(O17:O19) -> 3.0566667 | P20: =AVERAGE(P17:P19) -> 3.0566667 | Q20: =AVERAGE(Q17:Q19) -> 3.0566667 | R20: =AVERAGE(R17:R19) -> 3.0566667 | S20: =AVERAGE(S17:S19) -> 3.0566667 | T20: =AVERAGE(T17:T19) -> 3.0566667 | U20: =AVERAGE(U17:U19) -> 3.0566667 | ... Y20: =AVERAGE(Y17:Y19) -> 3.0566667
A21: SAL目標 | B21: 1.3 | C21: 2.3 | D21: 3 | E21: 3.4 | F21: 3.9 | G21: 4.3 | H21: 4.6 | I21: 4.9 | J21: 5.2 | K21: 6.2 | L21: 6.2 | M21: 6.2
A22: SQL目標 | B22: 0.5 | C22: 0.8 | D22: 0.9 | E22: 1.1 | F22: 1.2 | G22: 1.3 | H22: 1.4 | I22: 1.5 | J22: 1.6 | K22: 1.9 | L22: 1.9 | M22: 1.9 | Z22: =$AN22/12 -> 1.25 | AA22: =$AN22/12 -> 1.25 | AB22: =$AN22/12 -> 1.25 | AC22: =$AN22/12 -> 1.25 | AD22: =$AN22/12 -> 1.25 | AE22: =$AN22/12 -> 1.25 | AF22: =$AN22/12 -> 1.25 | AG22: =$AN22/12 -> 1.25 | ... AK22: =$AN22/12 -> 1.25 | AN22: 15
A23: SQL目標達成率 | H23: =IF(H15=0,"0%",H9/H22) -> 0 | I23: =IF(I15=0,"0%",I9/I22) -> 0 | J23: =IF(J15=0,"0%",J9/J22) -> 0 | K23: =IF(K15=0,"0%",K9/K22) -> 0 | L23: =IF(L15=0,"0%",L9/L22) -> 0 | M23: =IF(M15=0,"0%",M9/M22) -> 1.0526316 | N23: =IF(N15=0,"0%",N9/N22) -> 0% | O23: =IF(O15=0,"0%",O9/O22) -> 0% | ... Y23: =IF(Y15=0,"0%",Y9/Y22) -> 0% | Z23: =SUM($Z9:Z9)/SUM($Z22:Z22) -> 0 | AA23: =SUM($Z9:AA9)/SUM($Z22:AA22) -> 0 | AB23: =SUM($Z9:AB9)/SUM($Z22:AB22) -> 0 | AC23: =SUM($Z9:AC9)/SUM($Z22:AC22) -> 0 | AD23: =SUM($Z9:AD9)/SUM($Z22:AD22) -> 0 | AE23: =SUM($Z9:AE9)/SUM($Z22:AE22) -> 0 | AF23: =SUM($Z9:AF9)/SUM($Z22:AF22) -> 0 | AG23: =SUM($Z9:AG9)/SUM($Z22:AG22) -> 0 | ... AK23: =SUM($Z9:AK9)/SUM($Z22:AK22) -> 0 | AL23: =IF(AL15=0,"0%",AL9/AL22) -> 0% | AM23: =IF(AM15=0,"0%",AM9/AM22) -> 0% | AN23: =IF(AN15=0,"0%",AN9/AN22) -> 0
A24: SQL目標（昨年実績120％） | N24: {=ROUNDUP(SUM(($G$9:$M$9)*1.2)/12,0)} -> 1 | O24: {=ROUNDUP(SUM(($G$9:$M$9)*1.2)/12,0)} -> 1 | P24: {=ROUNDUP(SUM(($G$9:$M$9)*1.2)/12,0)} -> 1 | Q24: {=ROUNDUP(SUM(($G$9:$M$9)*1.2)/12,0)} -> 1 | R24: {=ROUNDUP(SUM(($G$9:$M$9)*1.2)/12,0)} -> 1 | S24: {=ROUNDUP(SUM(($G$9:$M$9)*1.2)/12,0)} -> 1 | T24: {=ROUNDUP(SUM(($G$9:$M$9)*1.2)/12,0)} -> 1 | U24: {=ROUNDUP(SUM(($G$9:$M$9)*1.2)/12,0)} -> 1 | ... Y24: {=ROUNDUP(SUM(($G$9:$M$9)*1.2)/12,0)} -> 1
A25: SQL目標（KWポテンシャル） | N25: =N18*0*1.2 -> 0 | O25: =O18*0*1.2 -> 0 | P25: =P18*0*1.2 -> 0 | Q25: =Q18*0*1.2 -> 0 | R25: =R18*0*1.2 -> 0 | S25: =S18*0*1.2 -> 0 | T25: =T18*0*1.2 -> 0 | U25: =U18*0*1.2 -> 0 | ... Y25: =Y18*0*1.2 -> 0
A26: SQL目標（今年度利益目標111%） | N26: =ROUNDUP(3.63/12,0) -> 1 | O26: =ROUNDUP(3.63/12,0) -> 1 | P26: =ROUNDUP(3.63/12,0) -> 1 | Q26: =ROUNDUP(3.63/12,0) -> 1 | R26: =ROUNDUP(3.63/12,0) -> 1 | S26: =ROUNDUP(3.63/12,0) -> 1 | T26: =ROUNDUP(3.63/12,0) -> 1 | U26: =ROUNDUP(3.63/12,0) -> 1 | ... Y26: =ROUNDUP(3.63/12,0) -> 1
A27: SQL目標（平均） | N27: =AVERAGE(N24:N26) -> 0.66666667 | O27: =AVERAGE(O24:O26) -> 0.66666667 | P27: =AVERAGE(P24:P26) -> 0.66666667 | Q27: =AVERAGE(Q24:Q26) -> 0.66666667 | R27: =AVERAGE(R24:R26) -> 0.66666667 | S27: =AVERAGE(S24:S26) -> 0.66666667 | T27: =AVERAGE(T24:T26) -> 0.66666667 | U27: =AVERAGE(U24:U26) -> 0.66666667 | ... Y27: =AVERAGE(Y24:Y26) -> 0.66666667
A28: 予算 | N28: 1287500 | O28: 1287500 | P28: 1175000 | Q28: 1175000 | R28: 1175000 | S28: 1175000
A29: 予算（実績） | B29: =SUM(#REF!,#REF!,#REF!) -> #REF! | C29: =SUM(#REF!,#REF!,#REF!) -> #REF! | D29: =SUM(#REF!,#REF!,#REF!) -> #REF! | E29: =SUM(#REF!,#REF!,#REF!) -> #REF! | F29: =SUM(#REF!,#REF!,#REF!) -> #REF! | G29: =SUM(#REF!,#REF!,#REF!) -> #REF! | H29: =SUM(#REF!,#REF!,#REF!) -> #REF! | I29: =SUM(#REF!,#REF!,#REF!) -> #REF! | ... M29: =SUM(#REF!,#REF!,#REF!) -> #REF! | N29: =SUM(N30:N37) -> 673043 | O29: =SUM(O30:O37) -> 645126 | P29: =SUM(P30:P37) -> 495145 | Q29: =SUM(Q30:Q37) -> 556696 | R29: =SUM(R30:R37) -> 735117 | S29: =SUM(S30:S37) -> 530449 | T29: =SUM(T30:T37) -> 315000 | U29: =SUM(U30:U37) -> 255000 | ... AK29: =SUM(AK30:AK37) -> 255000 | AL29: =SUM(B29:M29) -> #REF! | AM29: =SUM(N29:Y29) -> 6402457 | AN29: =SUM(Z29:AK29) -> 4424369
A30: 予算（実績）コラム | N30: ='[2]2025'!Z$90 -> 0 | O30: ='[2]2025'!AA$90 -> 0 | P30: ='[2]2025'!AB$90 -> 0 | Q30: ='[2]2025'!AC$90 -> 0 | R30: ='[2]2025'!AD$90 -> 220000 | S30: ='[2]2025'!AE$90 -> 0 | T30: ='[2]2025'!AF$90 -> 0 | U30: ='[2]2025'!AG$90 -> 0 | ... Y30: ='[2]2025'!AK$90 -> 143000 | Z30: ='[2]2026'!F$30 -> 246000 | AA30: ='[2]2026'!G$30 -> 0 | AB30: ='[2]2026'!H$30 -> 176000 | AC30: ='[2]2026'!I$30 -> 0 | AD30: ='[2]2026'!J$30 -> 0 | AE30: ='[2]2026'!K$30 -> 0 | AF30: ='[2]2026'!L$30 -> 0 | AG30: ='[2]2026'!M$30 -> 0 | ... AK30: ='[2]2026'!Q$30 -> 0 | AM30: =SUM(N30:Y30) -> 638000 | AN30: =SUM(Z30:AK30) -> 422000
A31: 予算（実績）メルマガ | N31: ='[2]2025'!Z$145 -> 30000 | O31: ='[2]2025'!AA$145 -> 30000 | P31: ='[2]2025'!AB$145 -> 30000 | Q31: ='[2]2025'!AC$145 -> 30000 | R31: ='[2]2025'!AD$145 -> 0 | S31: ='[2]2025'!AE$145 -> 30000 | T31: ='[2]2025'!AF$145 -> 60000 | U31: ='[2]2025'!AG$145 -> 0 | ... Y31: ='[2]2025'!AK$145 -> 0 | Z31: ='[2]2026'!F$97 -> 45000 | AA31: ='[2]2026'!G$97 -> 0 | AB31: ='[2]2026'!H$97 -> 90000 | AC31: ='[2]2026'!I$97 -> 0 | AD31: ='[2]2026'!J$97 -> 0 | AE31: ='[2]2026'!K$97 -> 0 | AF31: ='[2]2026'!L$97 -> 0 | AG31: ='[2]2026'!M$97 -> 0 | ... AK31: ='[2]2026'!Q$97 -> 0 | AM31: =SUM(N31:Y31) -> 330000 | AN31: =SUM(Z31:AK31) -> 135000
A32: 予算（実績）WP | N32: ='[2]2025'!Z$119 -> 0 | O32: ='[2]2025'!AA$119 -> 0 | P32: ='[2]2025'!AB$119 -> 0 | Q32: ='[2]2025'!AC$119 -> 0 | R32: ='[2]2025'!AD$119 -> 0 | S32: ='[2]2025'!AE$119 -> 0 | T32: ='[2]2025'!AF$119 -> 0 | U32: ='[2]2025'!AG$119 -> 0 | ... Y32: ='[2]2025'!AK$119 -> 0 | Z32: ='[2]2026'!F$67 -> 0 | AA32: ='[2]2026'!G$67 -> 0 | AB32: ='[2]2026'!H$67 -> 0 | AC32: ='[2]2026'!I$67 -> 0 | AD32: ='[2]2026'!J$67 -> 0 | AE32: ='[2]2026'!K$67 -> 0 | AF32: ='[2]2026'!L$67 -> 0 | AG32: ='[2]2026'!M$67 -> 0 | ... AK32: ='[2]2026'!Q$67 -> 0 | AM32: =SUM(N32:Y32) -> 0 | AN32: =SUM(Z32:AK32) -> 0
A33: 予算（実績）事例 | N33: ='[2]2025'!Z$165 -> 0 | O33: ='[2]2025'!AA$165 -> 0 | P33: ='[2]2025'!AB$165 -> 0 | Q33: ='[2]2025'!AC$165 -> 0 | R33: ='[2]2025'!AD$165 -> 0 | S33: ='[2]2025'!AE$165 -> 0 | T33: ='[2]2025'!AF$165 -> 0 | U33: ='[2]2025'!AG$165 -> 0 | ... Y33: ='[2]2025'!AK$165 -> 0 | Z33: ='[2]2026'!AL$165 -> 0 | AA33: ='[2]2026'!AM$165 -> 0 | AB33: ='[2]2026'!AN$165 -> 0 | AC33: ='[2]2026'!AO$165 -> 0 | AD33: ='[2]2026'!AP$165 -> 0 | AE33: ='[2]2026'!AQ$165 -> 0 | AF33: ='[2]2026'!AR$165 -> 0 | AG33: ='[2]2026'!AS$165 -> 0 | ... AK33: ='[2]2026'!AW$165 -> 0 | AM33: =SUM(N33:Y33) -> 0 | AN33: =SUM(Z33:AK33) -> 0
A34: 予算（実績）広告 | N34: 155543 | O34: 127626 | P34: 90145 | Q34: 151696 | R34: 140117 | S34: 125449 | T34: 0 | U34: 0 | V34: 176103 | W34: 160373 | X34: 151103 | Y34: 151302 | Z34: 201773 | AA34: 201830 | AB34: 201837 | AC34: 201929 | AM34: =SUM(N34:Z34) -> 1631230 | AN34: =SUM(Z34:AK34) -> 807369
A35: 予算（実績）Web運用 | N35: 0 | O35: 0 | P35: 0 | Q35: 0 | R35: 0 | S35: 0 | T35: 55000 | U35: 55000 | V35: 55000 | W35: 55000 | X35: 55000 | Y35: 55000 | Z35: 55000 | AA35: 55000 | AB35: 55000 | AC35: 55000 | AD35: 55000 | AE35: 55000 | AF35: 55000 | AG35: 55000 | AH35: 55000 | AI35: 55000 | AJ35: 55000 | AK35: 55000 | AM35: =SUM(N35:Y35) -> 330000 | AN35: =SUM(Z35:AK35) -> 660000
A36: 予算（実績）コンサル | N36: 487500 | O36: 487500 | P36: 375000 | Q36: 375000 | R36: 375000 | S36: 375000 | T36: 200000 | U36: 200000 | V36: 200000 | W36: 200000 | X36: 200000 | Y36: 200000 | Z36: 200000 | AA36: 200000 | AB36: 200000 | AC36: 200000 | AD36: 200000 | AE36: 200000 | AF36: 200000 | AG36: 200000 | AH36: 200000 | AI36: 200000 | AJ36: 200000 | AK36: 200000 | AM36: =SUM(N36:Y36) -> 3675000 | AN36: =SUM(Z36:AK36) -> 2400000
A37: 予算（実績）その他 | N37: 0 | O37: 0 | P37: 0 | Q37: 0 | R37: 0 | S37: 0 | T37: 0 | U37: 0 | V37: 0 | W37: 0 | X37: 0 | Y37: 0 | Z37: 0 | AA37: 0 | AB37: 0 | AC37: 0 | AD37: 0 | AE37: 0 | AF37: 0 | AG37: 0 | AH37: 0 | AI37: 0 | AJ37: 0 | AK37: 0 | AM37: =SUM(N37:Y37) -> 0 | AN37: =SUM(Z37:AK37) -> 0
A38: CV単価 | B38: =IFERROR(B$29/B56,"") | C38: =IFERROR(C$29/C56,"") | D38: =IFERROR(D$29/D56,"") | E38: =IFERROR(E$29/E56,"") | F38: =IFERROR(F$29/F56,"") | G38: =IFERROR(G$29/G58,"") | H38: =IFERROR(H$29/H58,"") | I38: =IFERROR(I$29/I58,"") | J38: =IFERROR(J$29/J58,"") | K38: =IFERROR(K$29/K58,"") | L38: =IFERROR(L$29/L58,"") | M38: =IFERROR(M$29/M58,"") | N38: =IF(N5=0,0,N$29/N5) -> 84130.375 | O38: =IF(O5=0,0,O$29/O5) -> 161281.5 | P38: =IF(P5=0,0,P$29/P5) -> 99029 | Q38: =IF(Q5=0,0,Q$29/Q5) -> 79528 | R38: =IF(R5=0,0,R$29/R5) -> 0 | S38: =IF(S5=0,0,S$29/S5) -> 265224.5 | T38: =IF(T5=0,0,T$29/T5) -> 105000 | U38: =IF(U5=0,0,U$29/U5) -> 255000 | ... AN38: =IF(AN5=0,0,AN$29/AN5) -> 260257
A39: SQL単価 | B39: =IFERROR(B$29/B9,"") | C39: =IFERROR(C$29/C9,"") | D39: =IFERROR(D$29/D9,"") | E39: =IFERROR(E$29/E9,"") | F39: =IFERROR(F$29/F9,"") | G39: =IFERROR(G$29/G9,"") | H39: =IFERROR(H$29/H9,"") | I39: =IFERROR(I$29/I9,"") | ... M39: =IFERROR(M$29/M9,"") | N39: =IF(N9=0,0,N$29/N9) -> 0 | O39: =IF(O9=0,0,O$29/O9) -> 0 | P39: =IF(P9=0,0,P$29/P9) -> 165048.33 | Q39: =IF(Q9=0,0,Q$29/Q9) -> 0 | R39: =IF(R9=0,0,R$29/R9) -> 735117 | S39: =IF(S9=0,0,S$29/S9) -> 0 | T39: =IF(T9=0,0,T$29/T9) -> 0 | U39: =IF(U9=0,0,U$29/U9) -> 0 | ... AN39: =IF(AN9=0,0,AN$29/AN9) -> 0
